Workbook

Sheet TOTAL
A1: TOTAL BUKU KAS UMUM
A3: Nama Madrasah | C3: : | D3: Yayasan | G3: Bulan | H3: : Dzulqo'dah
A4: Desa/Kecamatan | C4: : | D4: =SYAWAL!D4 -> Yayasan | G4: Halaman | H4: :
A5: Kabupaten | C5: : | D5: =SYAWAL!D5 -> Blu'uran, Karang Penang
A7: Tanggal (Masehi) | B7: Tanggal (Hijriyah) | C7: No. Kode | D7: No. Bukti | E7: URAIAN | G7: Penerimaan | H7: Pengeluaran | I7: Saldo
G8: (Rp) | H8: (Rp) | I8: (Rp)
A9: 1 | B9: 2 | C9: 3 | D9: 4 | E9: 5 | G9: 6 | H9: 7 | I9: 8
E10: Bulan Syawal | G10: =SYAWAL!H42 -> 0 | H10: =SYAWAL!I42 -> 0 | I10: =IF(OR(G10<>0,H10<>0),SUM(G10:G$11)-SUM(H10:H$11),0) -> 0
E11: Bulan Dzulqa'dah | G11: =DZULQADAH!G19 -> 50150000 | H11: =DZULQADAH!H19 -> 44855000 | I11: =IF(OR(G11<>0,H11<>0),SUM(G11:G$11)-SUM(H11:H$11),0) -> 5295000
E12: Bulan Dzulhijjah | G12: =DZULHIJJAH!G21 -> 57185000 | H12: =DZULHIJJAH!H21 -> 49169000 | I12: =IF(OR(G12<>0,H12<>0),SUM(G12:G$11)-SUM(H12:H$11),0) -> 13311000
E13: Bulan Shafar | G13: =MOHARROM!G29 -> 8016000 | H13: =MOHARROM!H29 -> 2185000 | I13: =IF(OR(G13<>0,H13<>0),SUM(G13:G$11)-SUM(H13:H$11),0) -> 19142000
E14: Bulan Muharrom | G14: =SHAFAR!G29 -> 5831000 | H14: =SHAFAR!H29 -> 0 | I14: =IF(OR(G14<>0,H14<>0),SUM(G14:G$11)-SUM(H14:H$11),0) -> 24973000
E15: Bulan Rabiul Awal | G15: ='RABIUL AWAL'!G37 -> 65957000 | H15: ='RABIUL AWAL'!H37 -> 55777000 | I15: =IF(OR(G15<>0,H15<>0),SUM(G15:G$11)-SUM(H15:H$11),0) -> 35153000
E16: Bulan Rabiul Tsani | G16: ='RABIUL TSANI'!G29 -> 23780000 | H16: ='RABIUL TSANI'!H29 -> 12120000 | I16: =IF(OR(G16<>0,H16<>0),SUM(G16:G$11)-SUM(H16:H$11),0) -> 46813000
E17: Bulan Jum Ula | G17: ='JUM ULA'!G29 -> 11660000 | H17: ='JUM ULA'!H29 -> 2170000 | I17: =IF(OR(G17<>0,H17<>0),SUM(G17:G$11)-SUM(H17:H$11),0) -> 56303000
E18: Bulan Jum Tsani | G18: ='JUM TSANI'!G23 -> 71843000 | H18: ='JUM TSANI'!H23 -> 68253000 | I18: =IF(OR(G18<>0,H18<>0),SUM(G18:G$11)-SUM(H18:H$11),0) -> 59893000
E19: Bulan Rajab | G19: =RAJAB!G29 -> 26178000 | H19: =RAJAB!H29 -> 26110000 | I19: =IF(OR(G19<>0,H19<>0),SUM(G19:G$11)-SUM(H19:H$11),0) -> 59961000
E20: Bulan Sya'ban | G20: =SYABAN!G29 -> 46128000 | H20: =SYABAN!H29 -> 41108000 | I20: =IF(OR(G20<>0,H20<>0),SUM(G20:G$11)-SUM(H20:H$11),0) -> 64981000
E21: Bulan Ramadhan | G21: =RAMADHAN!G30 -> 5020000 | H21: =RAMADHAN!H30 -> 0 | I21: =IF(OR(G21<>0,H21<>0),SUM(G21:G$11)-SUM(H21:H$11),0) -> 70001000
G22: =SUM(G10:G21) -> 371748000 | H22: =SUM(H10:H21) -> 301747000 | I22: =G22-H22 -> 70001000
A23: Pada hari ............. tanggal .......... Dzulqa'dah 1445, Buku Kas Umum ditutup dengan keadaan sebagai berikut :
A24: Saldo Buku Kas Umum | F24: =+I22 -> 70001000
A25: Terdiri dari :
A26: Saldo Kas Tunai (isi sendiri)
A27: Saldo Bank | E27: =I22-E26 -> 70001000
A28: Jumlah | F28: =SUM(E26:E27) -> 70001000
A30: Mengetahui, | G30: Sampang, .............................................
A31: Ketua Yayasan | G31: Bendahara Yayasan
A32: K. KHOIRUS SHOLEH | G32: .............................

Sheet SYAWAL
A2: BUKU KAS UMUM
A4: Nama Madrasah | C4: : | D4: Yayasan | H4: Bulan | I4: : Syawal
A5: Desa/Kecamatan | C5: : | D5: Blu'uran, Karang Penang | H5: Halaman | I5: :
A6: Kabupaten | C6: : | D6: Sampang
A8: Tanggal (Masehi) | B8: Tanggal (Hijriyah) | C8: No. Kode | D8: No. Bukti | E8: URAIAN | G8: SUMBER DANA | H8: Penerimaan | I8: Pengeluaran | J8: Saldo
H9: (Rp) | I9: (Rp) | J9: (Rp)
A10: 1 | B10: 2 | C10: 3 | D10: 4 | E10: 5 | G10: 6 | H10: 7 | I10: 8 | J10: 9
J11: =IF(OR(H11<>0,I11<>0),SUM(H$11:H11)-SUM(I$11:I11),0) -> 0
J12: =IF(OR(H12<>0,I12<>0),SUM(H$11:H12)-SUM(I$11:I12),0) -> 0
J13: =IF(OR(H13<>0,I13<>0),SUM(H$11:H13)-SUM(I$11:I13),0) -> 0
J14: =IF(OR(H14<>0,I14<>0),SUM(H$11:H14)-SUM(I$11:I14),0) -> 0
J15: =IF(OR(H15<>0,I15<>0),SUM(H$11:H15)-SUM(I$11:I15),0) -> 0
J16: =IF(OR(H16<>0,I16<>0),SUM(H$11:H16)-SUM(I$11:I16),0) -> 0
J17: =IF(OR(H17<>0,I17<>0),SUM(H$11:H17)-SUM(I$11:I17),0) -> 0
J18: =IF(OR(H18<>0,I18<>0),SUM(H$11:H18)-SUM(I$11:I18),0) -> 0
J19: =IF(OR(H19<>0,I19<>0),SUM(H$11:H19)-SUM(I$11:I19),0) -> 0
J20: =IF(OR(H20<>0,I20<>0),SUM(H$11:H20)-SUM(I$11:I20),0) -> 0
J21: =IF(OR(H21<>0,I21<>0),SUM(H$11:H21)-SUM(I$11:I21),0) -> 0
J22: =IF(OR(H22<>0,I22<>0),SUM(H$11:H22)-SUM(I$11:I22),0) -> 0
... J40: =IF(OR(H40<>0,I40<>0),SUM(H$11:H40)-SUM(I$11:I40),0) -> 0
E41: =IFERROR(VLOOKUP(C41,#REF!,2)," ") | J41: =IF(OR(H41<>0,I41<>0),SUM(H$11:H41)-SUM(I$11:I41),0) -> 0
H42: =SUM(H11:H41) -> 0 | I42: =SUM(I11:I41) -> 0 | J42: =H42-I42 -> 0
A43: Pada hari ................ tanggal ........... bulan.......... tahun .................. Buku Kas Umum ditutup dengan keadaan sebagai berikut :
A44: Saldo Buku Kas Umum | F44: =+J42 -> 0
A45: Terdiri dari :
A46: Saldo Kas Tunai (isi sendiri)
A47: Saldo Bank | E47: =J42-E46 -> 0
A48: Jumlah | F48: =SUM(E46:E47) -> 0
A50: Mengetahui, | I50: Sampang, .................................
A51: Ketua Yayasan | I51: Bendahara
A56: K. KHOIRUS SHOLEH | I56: .....................................

Sheet DZULQADAH
A2: BUKU KAS UMUM
A4: Nama Madrasah | C4: : | G4: Bulan | H4: : Dzulqo'dah
A5: Desa/Kecamatan | C5: : | D5: =SYAWAL!D5 -> Blu'uran, Karang Penang | G5: Halaman | H5: :
A6: Kabupaten | C6: : | D6: =SYAWAL!D6 -> Sampang
A8: Tanggal (Masehi) | B8: Tanggal (Hijriyah) | C8: No. Kode | D8: No. Bukti | E8: URAIAN | G8: Penerimaan | H8: Pengeluaran | I8: Saldo
G9: (Rp) | H9: (Rp) | I9: (Rp)
A10: 1 | B10: 2 | C10: 3 | D10: 4 | E10: 5 | G10: 6 | H10: 7 | I10: 8
D11: 1 | E11: Saldo Bulan Syawal | I11: =IF(OR(G11<>0,H11<>0),SUM(G$11:G11)-SUM(H$11:H11),0) -> 0
E12: SOUND | G12: 26100000 | H12: 23705000 | I12: =IF(OR(G12<>0,H12<>0),SUM(G$11:G12)-SUM(H$11:H12),0) -> 2395000
E13: PANGGUNG | G13: 11000000 | H13: 11400000 | I13: =SUM(G13-H13) -> -400000
E14: TENDA | G14: 10250000 | H14: 6750000 | I14: =IF(OR(G14<>0,H14<>0),SUM(G$11:G14)-SUM(H$11:H14),0) -> 5495000
E15: KURSI | G15: 2800000 | H15: 1400000 | I15: =IF(OR(G15<>0,H15<>0),SUM(G$11:G15)-SUM(H$11:H15),0) -> 6895000
E16: PERBAIKAN PESANTREN | H16: 1100000 | I16: =IF(OR(G16<>0,H16<>0),SUM(G$11:G16)-SUM(H$11:H16),0) -> 5795000
E17: SETOR KE MD UNTUK BAYAR GURU DALAM | H17: 500000 | I17: =IF(OR(G17<>0,H17<>0),SUM(G$11:G17)-SUM(H$11:H17),0) -> 5295000
E18: SETOR KE YAYASAN | I18: =IF(OR(G18<>0,H18<>0),SUM(G$11:G18)-SUM(H$11:H18),0) -> 0
G19: =SUM(G11:G18) -> 50150000 | H19: =SUM(H11:H18) -> 44855000 | I19: =G19-H19 -> 5295000
A20: Pada hari ................ tanggal ........... bulan.......... tahun .................. Buku Kas Umum ditutup dengan keadaan sebagai berikut :
A21: Saldo Buku Kas Umum | F21: =+I19 -> 5295000
A22: Terdiri dari :
A23: Saldo Kas Tunai (isi sendiri)
A24: Saldo Bank | E24: =I19-E23 -> 5295000
A25: Jumlah | F25: =SUM(E23:E24) -> 5295000
A27: Mengetahui, | G27: Sampang, ......................................1446
A28: Ketua Yayasan | G28: Bendahara
A33: K. KHOIRUS SHOLEH | G33: ..............................................
A47: BUKU KAS UMUM
A49: Nama Sekolah | D49: :
A50: Desa/Kecamatan | D50: :
A51: Kabupaten | D51: : Sleman | H51: Halaman :
A53: Tanggal | C53: No. Kode | D53: No. Bukti | E53: URAIAN | G53: Penerimaan | H53: Pengeluaran | I53: Saldo
G54: (Rp) | H54: (Rp) | I54: (Rp)
A55: 1 | C55: 2 | D55: 3 | E55: 4 | G55: 5 | H55: 6 | I55: 7
A56: 02-05-2015 | E56: Saldo bulan yang lalu | G56: =G19 -> 50150000 | H56: =H19 -> 44855000 | I56: =I19 -> 5295000
A57: 11-05-2015 | D57: 9 | E57: Langganan listrik bulan Mei 2015 | H57: =#REF! -> #REF! | I57: =I56-H57 -> #REF!
A58: 11-05-2015 | D58: 10 | E58: Langganan telpon bulan Mei 2015 | H58: =#REF! -> #REF! | I58: =I57-H58 -> #REF!
E65: Jumlah | G65: =SUM(G56:G64) -> 50150000 | H65: =SUM(H56:H64) -> #REF! | I65: =+G65-H65 -> #REF!
A66: Pada hari Sabtu tanggal 30 Mei 2015, Buku Kas Umum ditutup dengan keadaan sebagai berikut :
A67: Saldo Buku Kas Umum | F67: =I65 -> #REF!
A68: Terdiri dari :
A69: Saldo Kas Tunai | E69: =#REF! -> #REF!
...

Sheet DZULHIJJAH
A2: BUKU KAS UMUM
A4: Nama Madrasah | C4: : | D4: =DZULQADAH!D4 | G4: Bulan | H4: : Dzulhijjah
A5: Desa/Kecamatan | C5: : | D5: =DZULQADAH!D5 -> Blu'uran, Karang Penang | G5: Halaman | H5: :
A6: Kabupaten | C6: : | D6: =DZULQADAH!D6 -> Sampang
A8: Tanggal (Masehi) | B8: Tanggal (Hijriyah) | C8: No. Kode | D8: No. Bukti | E8: URAIAN | G8: Penerimaan | H8: Pengeluaran | I8: Saldo
G9: (Rp) | H9: (Rp) | I9: (Rp)
A10: 1 | C10: 3 | D10: 4 | E10: 5 | G10: 6 | H10: 7 | I10: 8
D11: 1 | E11: Saldo awal bulan Dzul Qo'dah | G11: =if(D11=1,DZULQADAH!I19,"") -> 5295000 | I11: =IF(OR(G11<>0,H11<>0),SUM(G$11:G11)-SUM(H$11:H11),0) -> 5295000
E12: SOUND | G12: 10300000 | H12: 2000000 | I12: =IF(OR(#REF!<>0,#REF!<>0),SUM(G$11:G11)-SUM(H$11:H11),0) -> #REF!
E13: PANGGUNG | G13: 38290000 | H13: 7400000 | I13: =IF(OR(#REF!<>0,H12<>0),SUM(G$11:G11)-SUM(H$11:H11),0) -> #REF!
E14: TENDA | G14: 3300000 | H14: 31334000 | I14: =IF(OR(G12<>0,H13<>0),SUM(G$11:G11)-SUM(H$11:H11),0) -> 5295000
E15: KURSI | H15: 1250000 | I15: =IF(OR(G13<>0,H14<>0),SUM(G$11:G11)-SUM(H$11:H11),0) -> 5295000
E16: PERBAIKAN PESANTREN | I16: =IF(OR(G14<>0,H15<>0),SUM(G$11:G14)-SUM(H$11:H11),0) -> 57185000
E17: DI SETOR KE MADRASAH UNTUK BIAYA IMDA 1 | H17: 5000000 | I17: =IF(OR(G17<>0,H16<>0),SUM(G$11:G17)-SUM(H$11:H11),0) -> 0
E18: DI SETOR KE Yayasan (Angsuran BRI) | H18: 2185000 | I18: =IF(OR(G18<>0,H17<>0),SUM(G$11:G18)-SUM(H$11:H17),0) -> 10201000
I19: =IF(OR(G19<>0,H19<>0),SUM(G$11:G19)-SUM(H$11:H19),0) -> 0
E20: =IFERROR(VLOOKUP(C20,#REF!,2)," ") | I20: =IF(OR(G20<>0,H20<>0),SUM(G$11:G20)-SUM(H$11:H20),0) -> 0
G21: =SUM(G11:G20) -> 57185000 | H21: =SUM(H11:H20) -> 49169000 | I21: =G21-H21 -> 8016000
A22: Pada hari ................ tanggal ........... bulan.......... tahun .................. Buku Kas Umum ditutup dengan keadaan sebagai berikut :
A23: Saldo Buku Kas Umum | F23: =+I21 -> 8016000
A24: Terdiri dari :
A25: Saldo Kas Tunai (isi sendiri)
A26: Saldo Bank | E26: =I21-E25 -> 8016000
A27: Jumlah | F27: =SUM(E25:E26) -> 8016000
A29: Mengetahui, | G29: Sampang,......................................
A30: =DZULQADAH!A28 -> Ketua Yayasan | G30: =DZULQADAH!G28 -> Bendahara
A35: =DZULQADAH!A33 -> K. KHOIRUS SHOLEH | G35: =DZULQADAH!G33 -> ..............................................
A49: BUKU KAS UMUM
A51: Nama Sekolah | D51: :
A52: Desa/Kecamatan | D52: :
A53: Kabupaten | D53: : Sleman | H53: Halaman :
A55: Tanggal | C55: No. Kode | D55: No. Bukti | E55: URAIAN | G55: Penerimaan | H55: Pengeluaran | I55: Saldo
G56: (Rp) | H56: (Rp) | I56: (Rp)
A57: 1 | C57: 2 | D57: 3 | E57: 4 | G57: 5 | H57: 6 | I57: 7
A58: 02-05-2015 | E58: Saldo bulan yang lalu | G58: =G21 -> 57185000 | H58: =H21 -> 49169000 | I58: =I21 -> 8016000
A59: 11-05-2015 | D59: 9 | E59: Langganan listrik bulan Mei 2015 | H59: =#REF! -> #REF! | I59: =I58-H59 -> #REF!
A60: 11-05-2015 | D60: 10 | E60: Langganan telpon bulan Mei 2015 | H60: =#REF! -> #REF! | I60: =I59-H60 -> #REF!
E67: Jumlah | G67: =SUM(G58:G66) -> 57185000 | H67: =SUM(H58:H66) -> #REF! | I67: =+G67-H67 -> #REF!
A68: Pada hari Sabtu tanggal 30 Mei 2015, Buku Kas Umum ditutup dengan keadaan sebagai berikut :
A69: Saldo Buku Kas Umum | F69: =I67 -> #REF!
...

Sheet MOHARROM
A2: BUKU KAS UMUM
A4: Nama Madrasah | C4: : | D4: =SHAFAR!D4 | G4: Bulan | H4: : Shafar
A5: Desa/Kecamatan | C5: : | D5: =SHAFAR!D5 -> Blu'uran, Karang Penang | G5: Halaman | H5: :
A6: Kabupaten | C6: : | D6: =SHAFAR!D6 -> Sampang
A8: Tanggal (Masehi) | B8: Tanggal (Hijriyah) | C8: No. Kode | D8: No. Bukti | E8: URAIAN | G8: Penerimaan | H8: Pengeluaran | I8: Saldo
G9: (Rp) | H9: (Rp) | I9: (Rp)
A10: 1 | B10: 2 | C10: 3 | D10: 4 | E10: 5 | G10: 6 | H10: 7 | I10: 8
D11: 1 | E11: Saldo Bulan Dzulhijjah | G11: =if(D11=1,DZULHIJJAH!I21,"") -> 8016000 | I11: =IF(OR(G11<>0,H11<>0),SUM(G$11:G11)-SUM(H$11:H11),0) -> 8016000
E12: SOUND | I12: =IF(OR(G12<>0,H12<>0),SUM(G$11:G12)-SUM(H$11:H12),0) -> 0
E13: PANGGUNG | I13: =IF(OR(G13<>0,H13<>0),SUM(G$11:G13)-SUM(H$11:H13),0) -> 0
E14: TENDA | I14: =IF(OR(G14<>0,H14<>0),SUM(G$11:G14)-SUM(H$11:H14),0) -> 0
E15: KURSI | I15: =IF(OR(G15<>0,H15<>0),SUM(G$11:G15)-SUM(H$11:H15),0) -> 0
E16: PERBAIKAN PESANTREN | I16: =IF(OR(G16<>0,H16<>0),SUM(G$11:G16)-SUM(H$11:H16),0) -> 0
E17: DI SETOR KE MADRASAH UNTUK BIAYA IMDA 1 | I17: =IF(OR(G17<>0,H17<>0),SUM(G$11:G17)-SUM(H$11:H17),0) -> 0
E18: Setor ke yayasan | H18: 2185000 | I18: =IF(OR(G18<>0,H18<>0),SUM(G$11:G18)-SUM(H$11:H18),0) -> 5831000
I19: =IF(OR(G19<>0,H19<>0),SUM(G$11:G19)-SUM(H$11:H19),0) -> 0
E20: =IFERROR(VLOOKUP(C20,#REF!,2)," ") | I20: =IF(OR(G20<>0,H20<>0),SUM(G$11:G20)-SUM(H$11:H20),0) -> 0
E21: =IFERROR(VLOOKUP(C21,#REF!,2)," ") | I21: =IF(OR(G21<>0,H21<>0),SUM(G$11:G21)-SUM(H$11:H21),0) -> 0
E22: =IFERROR(VLOOKUP(C22,#REF!,2)," ") | I22: =IF(OR(G22<>0,H22<>0),SUM(G$11:G22)-SUM(H$11:H22),0) -> 0
E23: =IFERROR(VLOOKUP(C23,#REF!,2)," ") | I23: =IF(OR(G23<>0,H23<>0),SUM(G$11:G23)-SUM(H$11:H23),0) -> 0
E24: =IFERROR(VLOOKUP(C24,#REF!,2)," ") | I24: =IF(OR(G24<>0,H24<>0),SUM(G$11:G24)-SUM(H$11:H24),0) -> 0
E25: =IFERROR(VLOOKUP(C25,#REF!,2)," ") | I25: =IF(OR(G25<>0,H25<>0),SUM(G$11:G25)-SUM(H$11:H25),0) -> 0
E26: =IFERROR(VLOOKUP(C26,#REF!,2)," ") | I26: =IF(OR(G26<>0,H26<>0),SUM(G$11:G26)-SUM(H$11:H26),0) -> 0
E27: =IFERROR(VLOOKUP(C27,#REF!,2)," ") | I27: =IF(OR(G27<>0,H27<>0),SUM(G$11:G27)-SUM(H$11:H27),0) -> 0
E28: =IFERROR(VLOOKUP(C28,#REF!,2)," ") | I28: =IF(OR(G28<>0,H28<>0),SUM(G$11:G28)-SUM(H$11:H28),0) -> 0
G29: =SUM(G11:G28) -> 8016000 | H29: =SUM(H11:H28) -> 2185000 | I29: =G29-H29 -> 5831000
A30: Pada hari ................ tanggal ........... bulan.......... tahun .................. Buku Kas Umum ditutup dengan keadaan sebagai berikut :
A31: Saldo Buku Kas Umum | F31: =+I29 -> 5831000
A32: Terdiri dari :
A33: Saldo Kas Tunai (isi sendiri)
A34: Saldo Bank | E34: =I29-E33 -> 5831000
A35: Jumlah | F35: =SUM(E33:E34) -> 5831000
A37: Mengetahui, | G37: Sampang,.........................................
A38: =SHAFAR!A38 -> Ketua Yayasan | G38: =SHAFAR!G38 -> Bendahara
A43: =SHAFAR!A43 -> K. KHOIRUS SHOLEH | G43: =SHAFAR!G43 -> ..............................................
A57: BUKU KAS UMUM
A59: Nama Sekolah | D59: :
A60: Desa/Kecamatan | D60: :
A61: Kabupaten | D61: : Sleman | H61: Halaman :
A63: Tanggal | C63: No. Kode | D63: No. Bukti | E63: URAIAN | G63: Penerimaan | H63: Pengeluaran | I63: Saldo
...

Sheet SHAFAR
A2: BUKU KAS UMUM
A4: Nama Madrasah | C4: : | D4: =DZULHIJJAH!D4 | G4: Bulan | H4: : Muharram
A5: Desa/Kecamatan | C5: : | D5: =DZULHIJJAH!D5 -> Blu'uran, Karang Penang | G5: Halaman | H5: :
A6: Kabupaten | C6: : | D6: =DZULHIJJAH!D6 -> Sampang
A8: Tanggal (Masehi) | B8: Tanggal (Hijriyah) | C8: No. Kode | D8: No. Bukti | E8: URAIAN | G8: Penerimaan | H8: Pengeluaran | I8: Saldo
G9: (Rp) | H9: (Rp) | I9: (Rp)
A10: 1 | B10: 2 | C10: 3 | D10: 4 | E10: 5 | G10: 6 | H10: 7 | I10: 8
D11: 1 | E11: Saldo Bulan Muharrom | G11: =if(D11=1,MOHARROM!I29,"") -> 5831000 | I11: =IF(OR(G11<>0,H11<>0),SUM(G$11:G11)-SUM(H$11:H11),0) -> 5831000
E12: SOUND | I12: =IF(OR(G12<>0,H12<>0),SUM(G$11:G12)-SUM(H$11:H12),0) -> 0
E13: PANGGUNG | I13: =IF(OR(G13<>0,H13<>0),SUM(G$11:G13)-SUM(H$11:H13),0) -> 0
E14: TENDA | I14: =IF(OR(G14<>0,H14<>0),SUM(G$11:G14)-SUM(H$11:H14),0) -> 0
E15: KURSI | I15: =IF(OR(G15<>0,H15<>0),SUM(G$11:G15)-SUM(H$11:H15),0) -> 0
E16: PERBAIKAN PESANTREN | I16: =IF(OR(G16<>0,H16<>0),SUM(G$11:G16)-SUM(H$11:H16),0) -> 0
E17: DI SETOR KE MADRASAH UNTUK BIAYA IMDA 1 | I17: =IF(OR(G17<>0,H17<>0),SUM(G$11:G17)-SUM(H$11:H17),0) -> 0
E18: DI SETOR KE YAYASAN | I18: =IF(OR(G18<>0,H18<>0),SUM(G$11:G18)-SUM(H$11:H18),0) -> 0
I19: =IF(OR(G19<>0,H19<>0),SUM(G$11:G19)-SUM(H$11:H19),0) -> 0
E20: =IFERROR(VLOOKUP(C20,#REF!,2)," ") | I20: =IF(OR(G20<>0,H20<>0),SUM(G$11:G20)-SUM(H$11:H20),0) -> 0
E21: =IFERROR(VLOOKUP(C21,#REF!,2)," ") | I21: =IF(OR(G21<>0,H21<>0),SUM(G$11:G21)-SUM(H$11:H21),0) -> 0
E22: =IFERROR(VLOOKUP(C22,#REF!,2)," ") | I22: =IF(OR(G22<>0,H22<>0),SUM(G$11:G22)-SUM(H$11:H22),0) -> 0
E23: =IFERROR(VLOOKUP(C23,#REF!,2)," ") | I23: =IF(OR(G23<>0,H23<>0),SUM(G$11:G23)-SUM(H$11:H23),0) -> 0
I24: =IF(OR(G24<>0,H24<>0),SUM(G$11:G24)-SUM(H$11:H24),0) -> 0
E25: =IFERROR(VLOOKUP(C25,#REF!,2)," ") | I25: =IF(OR(G25<>0,H25<>0),SUM(G$11:G25)-SUM(H$11:H25),0) -> 0
E26: =IFERROR(VLOOKUP(C26,#REF!,2)," ") | I26: =IF(OR(G26<>0,H26<>0),SUM(G$11:G26)-SUM(H$11:H26),0) -> 0
E27: =IFERROR(VLOOKUP(C27,#REF!,2)," ") | I27: =IF(OR(G27<>0,H27<>0),SUM(G$11:G27)-SUM(H$11:H27),0) -> 0
E28: =IFERROR(VLOOKUP(C28,#REF!,2)," ") | I28: =IF(OR(G28<>0,H28<>0),SUM(G$11:G28)-SUM(H$11:H28),0) -> 0
G29: =SUM(G11:G28) -> 5831000 | H29: =SUM(H11:H28) -> 0 | I29: =G29-H29 -> 5831000
A30: Pada hari ................ tanggal ........... bulan.......... tahun .................. Buku Kas Umum ditutup dengan keadaan sebagai berikut :
A31: Saldo Buku Kas Umum | F31: =+I29 -> 5831000
A32: Terdiri dari :
A33: Saldo Kas Tunai (isi sendiri)
A34: Saldo Bank | E34: =I29-E33 -> 5831000
A35: Jumlah | F35: =SUM(E33:E34) -> 5831000
A37: Mengetahui, | G37: Sampang, ...................................................
A38: =DZULHIJJAH!A30 -> Ketua Yayasan | G38: =DZULHIJJAH!G30 -> Bendahara
A43: =DZULHIJJAH!A35 -> K. KHOIRUS SHOLEH | G43: =DZULHIJJAH!G35 -> ..............................................
A57: BUKU KAS UMUM
A59: Nama Sekolah | D59: :
A60: Desa/Kecamatan | D60: :
A61: Kabupaten | D61: : Sleman | H61: Halaman :
A63: Tanggal | C63: No. Kode | D63: No. Bukti | E63: URAIAN | G63: Penerimaan | H63: Pengeluaran | I63: Saldo
...

Sheet RABIUL AWAL
A2: BUKU KAS UMUM
A4: Nama Madrasah | C4: : | D4: =MOHARROM!D4 | G4: Bulan | H4: : Rabiul Awal
A5: Desa/Kecamatan | C5: : | D5: =MOHARROM!D5 -> Blu'uran, Karang Penang | G5: Halaman | H5: :
A6: Kabupaten | C6: : | D6: =MOHARROM!D6 -> Sampang
A8: Tanggal (Masehi) | B8: Tanggal (Hijriyah) | C8: No. Kode | D8: No. Bukti | E8: URAIAN | G8: Penerimaan | H8: Pengeluaran | I8: Saldo
G9: (Rp) | H9: (Rp) | I9: (Rp)
A10: 1 | B10: 2 | C10: 3 | D10: 4 | E10: 5 | G10: 6 | H10: 7 | I10: 8
D11: 1 | E11: Saldo awal Bulan Muharrom | G11: 6331000 | I11: =IF(OR(G11<>0,H11<>0),SUM(G$11:G11)-SUM(H$11:H11),0) -> 6331000
E12: SOUND | G12: 32465000 | H12: 30149000 | I12: =IF(OR(G12<>0,H12<>0),SUM(G$11:G12)-SUM(H$11:H12),0) -> 8647000
E13: PANGGUNG | G13: 19700000 | H13: 18438000 | I13: =IF(OR(G13<>0,H13<>0),SUM(G$11:G13)-SUM(H$11:H13),0) -> 9909000
E14: TENDA | G14: 7461000 | H14: 2890000 | I14: =IF(OR(G14<>0,H14<>0),SUM(G$11:G14)-SUM(H$11:H14),0) -> 14480000
E15: KURSI | I15: =IF(OR(G15<>0,H15<>0),SUM(G$11:G15)-SUM(H$11:H15),0) -> 0
E16: PERBAIKAN PESANTREN | I16: =IF(OR(G16<>0,H16<>0),SUM(G$11:G16)-SUM(H$11:H16),0) -> 0
E17: DI SETOR KE MADRASAH UNTUK BIAYA IMDA 1 | I17: =IF(OR(G17<>0,H17<>0),SUM(G$11:G17)-SUM(H$11:H17),0) -> 0
E18: DI SETOR KE YAYASAN | H18: 4300000 | I18: =IF(OR(G18<>0,H18<>0),SUM(G$11:G18)-SUM(H$11:H18),0) -> 10180000
I19: =IF(OR(G19<>0,H19<>0),SUM(G$11:G19)-SUM(H$11:H19),0) -> 0
I20: =IF(OR(G20<>0,H20<>0),SUM(G$11:G20)-SUM(H$11:H20),0) -> 0
I21: =IF(OR(G21<>0,H21<>0),SUM(G$11:G21)-SUM(H$11:H21),0) -> 0
I22: =IF(OR(G22<>0,H22<>0),SUM(G$11:G22)-SUM(H$11:H22),0) -> 0
I23: =IF(OR(G23<>0,H23<>0),SUM(G$11:G23)-SUM(H$11:H23),0) -> 0
I24: =IF(OR(G24<>0,H24<>0),SUM(G$11:G24)-SUM(H$11:H24),0) -> 0
I25: =IF(OR(G25<>0,H25<>0),SUM(G$11:G25)-SUM(H$11:H25),0) -> 0
I26: =IF(OR(G26<>0,H26<>0),SUM(G$11:G26)-SUM(H$11:H26),0) -> 0
I27: =IF(OR(G27<>0,H27<>0),SUM(G$11:G27)-SUM(H$11:H27),0) -> 0
I28: =IF(OR(G28<>0,H28<>0),SUM(G$11:G28)-SUM(H$11:H28),0) -> 0
I29: =IF(OR(G29<>0,H29<>0),SUM(G$11:G29)-SUM(H$11:H29),0) -> 0
I30: =IF(OR(G30<>0,H30<>0),SUM(G$11:G30)-SUM(H$11:H30),0) -> 0
... I35: =IF(OR(G35<>0,H35<>0),SUM(G$11:G35)-SUM(H$11:H35),0) -> 0
E36: =IFERROR(VLOOKUP(C36,#REF!,2)," ") | I36: =IF(OR(G36<>0,H36<>0),SUM(G$11:G36)-SUM(H$11:H36),0) -> 0
G37: =SUM(G11:G36) -> 65957000 | H37: =SUM(H11:H36) -> 55777000 | I37: =G37-H37 -> 10180000
A38: Pada hari ................ tanggal ........... bulan.......... tahun .................. Buku Kas Umum ditutup dengan keadaan sebagai berikut :
A39: Saldo Buku Kas Umum | F39: =+I37 -> 10180000
A40: Terdiri dari :
A41: Saldo Kas Tunai (isi sendiri)
A42: Saldo Bank | E42: =I37-E41 -> 10180000
A43: Jumlah | F43: =SUM(E41:E42) -> 10180000
A45: Mengetahui, | G45: Sampang, .....................................................
A46: =MOHARROM!A38 -> Ketua Yayasan | G46: =MOHARROM!G38 -> Bendahara
A51: =MOHARROM!A43 -> K. KHOIRUS SHOLEH | G51: =MOHARROM!G43 -> ..............................................
A65: BUKU KAS UMUM
...

Sheet RABIUL TSANI
A2: BUKU KAS UMUM
A4: Nama Madrasah | C4: : | D4: ='RABIUL AWAL'!D4 | G4: Bulan | H4: : Rabiul Tsani
A5: Desa/Kecamatan | C5: : | D5: ='RABIUL AWAL'!D5 -> Blu'uran, Karang Penang | G5: Halaman | H5: :
A6: Kabupaten | C6: : | D6: ='RABIUL AWAL'!D6 -> Sampang
A8: Tanggal (Masehi) | B8: Tanggal (Hijriyah) | C8: No. Kode | D8: No. Bukti | E8: URAIAN | G8: Penerimaan | H8: Pengeluaran | I8: Saldo
G9: (Rp) | H9: (Rp) | I9: (Rp)
A10: 1 | B10: 2 | C10: 3 | D10: 4 | E10: 5 | G10: 6 | H10: 7 | I10: 8
D11: 1 | E11: Saldo Awal Bulan R. Awal | G11: =if(D11=1,'RABIUL AWAL'!I37,"") -> 10180000 | I11: =IF(OR(G11<>0,H11<>0),SUM(G$11:G11)-SUM(H$11:H11),0) -> 10180000
E12: SOUND | I12: =IF(OR(G12<>0,H12<>0),SUM(G$11:G12)-SUM(H$11:H12),0) -> 0
E13: PANGGUNG | G13: 9600000 | H13: 8650000 | I13: =IF(OR(G13<>0,H13<>0),SUM(G$11:G13)-SUM(H$11:H13),0) -> 11130000
E14: TENDA | G14: 4000000 | H14: 1300000 | I14: =IF(OR(G14<>0,H14<>0),SUM(G$11:G14)-SUM(H$11:H14),0) -> 13830000
E15: KURSI | I15: =IF(OR(G15<>0,H15<>0),SUM(G$11:G15)-SUM(H$11:H15),0) -> 0
E16: PERBAIKAN PESANTREN | I16: =IF(OR(G16<>0,H16<>0),SUM(G$11:G16)-SUM(H$11:H16),0) -> 0
E17: DI SETOR KE MADRASAH UNTUK BIAYA IMDA 1 | I17: =IF(OR(G17<>0,H17<>0),SUM(G$11:G17)-SUM(H$11:H17),0) -> 0
E18: DI SETOR KE YAYASAN | H18: 2170000 | I18: =IF(OR(G18<>0,H18<>0),SUM(G$11:G18)-SUM(H$11:H18),0) -> 11660000
I19: =IF(OR(G19<>0,H19<>0),SUM(G$11:G19)-SUM(H$11:H19),0) -> 0
E20: =IFERROR(VLOOKUP(C20,#REF!,2)," ") | I20: =IF(OR(G20<>0,H20<>0),SUM(G$11:G20)-SUM(H$11:H20),0) -> 0
E21: =IFERROR(VLOOKUP(C21,#REF!,2)," ") | I21: =IF(OR(G21<>0,H21<>0),SUM(G$11:G21)-SUM(H$11:H21),0) -> 0
E22: =IFERROR(VLOOKUP(C22,#REF!,2)," ") | I22: =IF(OR(G22<>0,H22<>0),SUM(G$11:G22)-SUM(H$11:H22),0) -> 0
E23: =IFERROR(VLOOKUP(C23,#REF!,2)," ") | I23: =IF(OR(G23<>0,H23<>0),SUM(G$11:G23)-SUM(H$11:H23),0) -> 0
E24: =IFERROR(VLOOKUP(C24,#REF!,2)," ") | I24: =IF(OR(G24<>0,H24<>0),SUM(G$11:G24)-SUM(H$11:H24),0) -> 0
E25: =IFERROR(VLOOKUP(C25,#REF!,2)," ") | I25: =IF(OR(G25<>0,H25<>0),SUM(G$11:G25)-SUM(H$11:H25),0) -> 0
E26: =IFERROR(VLOOKUP(C26,#REF!,2)," ") | I26: =IF(OR(G26<>0,H26<>0),SUM(G$11:G26)-SUM(H$11:H26),0) -> 0
E27: =IFERROR(VLOOKUP(C27,#REF!,2)," ") | I27: =IF(OR(G27<>0,H27<>0),SUM(G$11:G27)-SUM(H$11:H27),0) -> 0
E28: =IFERROR(VLOOKUP(C28,#REF!,2)," ") | I28: =IF(OR(G28<>0,H28<>0),SUM(G$11:G28)-SUM(H$11:H28),0) -> 0
G29: =SUM(G11:G28) -> 23780000 | H29: =SUM(H11:H28) -> 12120000 | I29: =G29-H29 -> 11660000
A30: Pada hari ................ tanggal ........... bulan.......... tahun .................. Buku Kas Umum ditutup dengan keadaan sebagai berikut :
A31: Saldo Buku Kas Umum | F31: =+I29 -> 11660000
A32: Terdiri dari :
A33: Saldo Kas Tunai (isi sendiri)
A34: Saldo Bank | E34: =I29-E33 -> 11660000
A35: Jumlah | F35: =SUM(E33:E34) -> 11660000
A37: Mengetahui, | G37: Sampang, .......................................................
A38: ='RABIUL AWAL'!A46 -> Ketua Yayasan | G38: ='RABIUL AWAL'!G46 -> Bendahara
A43: ='RABIUL AWAL'!A51 -> K. KHOIRUS SHOLEH | G43: ='RABIUL AWAL'!G51 -> ..............................................
A57: BUKU KAS UMUM
A59: Nama Sekolah | D59: :
A60: Desa/Kecamatan | D60: :
A61: Kabupaten | D61: : Sleman | H61: Halaman :
A63: Tanggal | C63: No. Kode | D63: No. Bukti | E63: URAIAN | G63: Penerimaan | H63: Pengeluaran | I63: Saldo
...

Sheet JUM ULA
A2: BUKU KAS UMUM
A4: Nama Madrasah | C4: : | D4: ='RABIUL TSANI'!D4 | G4: Bulan | H4: : Jumadal Ula
A5: Desa/Kecamatan | C5: : | D5: ='RABIUL TSANI'!D5 -> Blu'uran, Karang Penang | G5: Halaman | H5: :
A6: Kabupaten | C6: : | D6: ='RABIUL TSANI'!D6 -> Sampang
A8: Tanggal (Masehi) | B8: Tanggal (Hijriyah) | C8: No. Kode | D8: No. Bukti | E8: URAIAN | G8: Penerimaan | H8: Pengeluaran | I8: Saldo
G9: (Rp) | H9: (Rp) | I9: (Rp)
A10: 1 | B10: 2 | C10: 3 | D10: 4 | E10: 5 | G10: 6 | H10: 7 | I10: 8
D11: 1 | E11: Saldo Awal Bulan R. Tsani | G11: =if(D11=1,'RABIUL TSANI'!I29,"") -> 11660000 | I11: =IF(OR(G11<>0,H11<>0),SUM(G$11:G11)-SUM(H$11:H11),0) -> 11660000
E12: SOUND | I12: =IF(OR(G12<>0,H12<>0),SUM(G$11:G12)-SUM(H$11:H12),0) -> 0
E13: PANGGUNG | I13: =IF(OR(G13<>0,H13<>0),SUM(G$11:G13)-SUM(H$11:H13),0) -> 0
E14: TENDA | I14: =IF(OR(G14<>0,H14<>0),SUM(G$11:G14)-SUM(H$11:H14),0) -> 0
E15: KURSI | I15: =IF(OR(G15<>0,H15<>0),SUM(G$11:G15)-SUM(H$11:H15),0) -> 0
I16: =IF(OR(G16<>0,H16<>0),SUM(G$11:G16)-SUM(H$11:H16),0) -> 0
E17: DI SETOR KE MADRASAH UNTUK BIAYA IMDA 1 | H17: 2170000 | I17: =IF(OR(G17<>0,H17<>0),SUM(G$11:G17)-SUM(H$11:H17),0) -> 9490000
E18: DI SETOR KE YAYASAN | I18: =IF(OR(G18<>0,H18<>0),SUM(G$11:G18)-SUM(H$11:H18),0) -> 0
E19: =IFERROR(VLOOKUP(C19,#REF!,2)," ") | I19: =IF(OR(G19<>0,H19<>0),SUM(G$11:G19)-SUM(H$11:H19),0) -> 0
E20: =IFERROR(VLOOKUP(C20,#REF!,2)," ") | I20: =IF(OR(G20<>0,H20<>0),SUM(G$11:G20)-SUM(H$11:H20),0) -> 0
E21: =IFERROR(VLOOKUP(C21,#REF!,2)," ") | I21: =IF(OR(G21<>0,H21<>0),SUM(G$11:G21)-SUM(H$11:H21),0) -> 0
E22: =IFERROR(VLOOKUP(C22,#REF!,2)," ") | I22: =IF(OR(G22<>0,H22<>0),SUM(G$11:G22)-SUM(H$11:H22),0) -> 0
E23: =IFERROR(VLOOKUP(C23,#REF!,2)," ") | I23: =IF(OR(G23<>0,H23<>0),SUM(G$11:G23)-SUM(H$11:H23),0) -> 0
E24: =IFERROR(VLOOKUP(C24,#REF!,2)," ") | I24: =IF(OR(G24<>0,H24<>0),SUM(G$11:G24)-SUM(H$11:H24),0) -> 0
E25: =IFERROR(VLOOKUP(C25,#REF!,2)," ") | I25: =IF(OR(G25<>0,H25<>0),SUM(G$11:G25)-SUM(H$11:H25),0) -> 0
E26: =IFERROR(VLOOKUP(C26,#REF!,2)," ") | I26: =IF(OR(G26<>0,H26<>0),SUM(G$11:G26)-SUM(H$11:H26),0) -> 0
E27: =IFERROR(VLOOKUP(C27,#REF!,2)," ") | I27: =IF(OR(G27<>0,H27<>0),SUM(G$11:G27)-SUM(H$11:H27),0) -> 0
E28: =IFERROR(VLOOKUP(C28,#REF!,2)," ") | I28: =IF(OR(G28<>0,H28<>0),SUM(G$11:G28)-SUM(H$11:H28),0) -> 0
G29: =SUM(G11:G28) -> 11660000 | H29: =SUM(H11:H28) -> 2170000 | I29: =G29-H29 -> 9490000
A30: Pada hari ................ tanggal ........... bulan.......... tahun .................. Buku Kas Umum ditutup dengan keadaan sebagai berikut :
A31: Saldo Buku Kas Umum | F31: =+I29 -> 9490000
A32: Terdiri dari :
A33: Saldo Kas Tunai (isi sendiri)
A34: Saldo Bank | E34: =I29-E33 -> 9490000
A35: Jumlah | F35: =SUM(E33:E34) -> 9490000
A37: Mengetahui, | G37: Sampang, .................................................
A38: ='RABIUL TSANI'!A38 -> Ketua Yayasan | G38: ='RABIUL TSANI'!G38 -> Bendahara
A43: ='RABIUL TSANI'!A43 -> K. KHOIRUS SHOLEH | G43: ='RABIUL TSANI'!G43 -> ..............................................
A57: BUKU KAS UMUM
A59: Nama Sekolah | D59: :
A60: Desa/Kecamatan | D60: :
A61: Kabupaten | D61: : Sleman | H61: Halaman :
A63: Tanggal | C63: No. Kode | D63: No. Bukti | E63: URAIAN | G63: Penerimaan | H63: Pengeluaran | I63: Saldo
...

Sheet JUM TSANI
A2: BUKU KAS UMUM
A4: Nama Madrasah | C4: : | D4: ='JUM ULA'!D4 | G4: Bulan | H4: : Jumadas Tsani
A5: Desa/Kecamatan | C5: : | D5: ='JUM ULA'!D5 -> Blu'uran, Karang Penang | G5: Halaman | H5: :
A6: Kabupaten | C6: : | D6: ='JUM ULA'!D6 -> Sampang
A8: Tanggal (Masehi) | B8: Tanggal (Hijriyah) | C8: No. Kode | D8: No. Bukti | E8: URAIAN | G8: Penerimaan | H8: Pengeluaran | I8: Saldo
G9: (Rp) | H9: (Rp) | I9: (Rp)
A10: 1 | B10: 2 | C10: 3 | D10: 4 | E10: 5 | G10: 6 | H10: 7 | I10: 8
D11: 1 | E11: Saldo Awal Bulan J. Ula | G11: =if(D11=1,'JUM ULA'!I29,"") -> 9490000 | I11: =IF(OR(G11<>0,H11<>0),SUM(G$11:G11)-SUM(H$11:H11),0) -> 9490000
E12: SOUND | G12: 15020000 | H12: 25950000 | I12: =IF(OR(G12<>0,H12<>0),SUM(G$11:G12)-SUM(H$11:H12),0) -> -1440000
E13: PANGGUNG | G13: 18462000 | H13: 17510000 | I13: =IF(OR(G13<>0,H13<>0),SUM(G$11:G13)-SUM(H$11:H13),0) -> -488000
E14: TENDA | G14: 26021000 | H14: 19923000 | I14: =IF(OR(G14<>0,H14<>0),SUM(G$11:G14)-SUM(H$11:H14),0) -> 5610000
E15: KURSI | G15: 2850000 | H15: 1400000 | I15: =IF(OR(G15<>0,H15<>0),SUM(G$11:G15)-SUM(H$11:H15),0) -> 7060000
E16: PERBAIKAN KANTOR SMK SAKLAR+LAMPU +RAPAT YAYASAN | H16: 200000 | I16: =IF(OR(G16<>0,H16<>0),SUM(G$11:G16)-SUM(H$11:H16),0) -> 6860000
E17: DI SETOR KE MD UNTUK BIAYA LOMBA MUAMMAR | H17: 500000 | I17: =IF(OR(G17<>0,H17<>0),SUM(G$11:G17)-SUM(H$11:H17),0) -> 6360000
E18: DI SETOR KE YAYASAN | H18: 2170000 | I18: =IF(OR(G18<>0,H18<>0),SUM(G$11:G18)-SUM(H$11:H18),0) -> 4190000
E19: Laporan aset | H19: 600000 | I19: =IF(OR(G19<>0,H19<>0),SUM(G$11:G19)-SUM(H$11:H19),0) -> 3590000
E20: =IFERROR(VLOOKUP(C20,#REF!,2)," ") | I20: =IF(OR(G20<>0,H20<>0),SUM(G$11:G20)-SUM(H$11:H20),0) -> 0
E21: =IFERROR(VLOOKUP(C21,#REF!,2)," ") | I21: =IF(OR(G21<>0,H21<>0),SUM(G$11:G21)-SUM(H$11:H21),0) -> 0
E22: =IFERROR(VLOOKUP(C22,#REF!,2)," ") | I22: =IF(OR(G22<>0,H22<>0),SUM(G$11:G22)-SUM(H$11:H22),0) -> 0
G23: =SUM(G11:G22) -> 71843000 | H23: =SUM(H11:H22) -> 68253000 | I23: =SUM(G23-H23) -> 3590000
A24: Pada hari ................ tanggal ........... bulan.......... tahun .................. Buku Kas Umum ditutup dengan keadaan sebagai berikut :
A25: Saldo Buku Kas Umum | F25: =+I23 -> 3590000
A26: Terdiri dari :
A27: Saldo Kas Tunai (isi sendiri)
A28: Saldo Bank | E28: =I23-E27 -> 3590000
A29: Jumlah | F29: =SUM(E27:E28) -> 3590000
A31: Mengetahui, | G31: Sampang, .............................................
A32: ='JUM ULA'!A38 -> Ketua Yayasan | G32: ='JUM ULA'!G38 -> Bendahara
A37: ='JUM ULA'!A43 -> K. KHOIRUS SHOLEH | G37: ='JUM ULA'!G43 -> ..............................................
A51: BUKU KAS UMUM
A53: Nama Sekolah | D53: :
A54: Desa/Kecamatan | D54: :
A55: Kabupaten | D55: : Sleman | H55: Halaman :
A57: Tanggal | C57: No. Kode | D57: No. Bukti | E57: URAIAN | G57: Penerimaan | H57: Pengeluaran | I57: Saldo
G58: (Rp) | H58: (Rp) | I58: (Rp)
A59: 1 | C59: 2 | D59: 3 | E59: 4 | G59: 5 | H59: 6 | I59: 7
A60: 02-05-2015 | E60: Saldo bulan yang lalu | G60: =G23 -> 71843000 | H60: =H23 -> 68253000 | I60: =I23 -> 3590000
A61: 11-05-2015 | D61: 9 | E61: Langganan listrik bulan Mei 2015 | H61: =#REF! -> #REF! | I61: =I60-H61 -> #REF!
A62: 11-05-2015 | D62: 10 | E62: Langganan telpon bulan Mei 2015 | H62: =#REF! -> #REF! | I62: =I61-H62 -> #REF!
E69: Jumlah | G69: =SUM(G60:G68) -> 71843000 | H69: =SUM(H60:H68) -> #REF! | I69: =+G69-H69 -> #REF!
...

Sheet RAJAB
A2: BUKU KAS UMUM
A4: Nama Madrasah | C4: : | D4: ='JUM TSANI'!D4 | G4: Bulan | H4: : Rajab
A5: Desa/Kecamatan | C5: : | D5: ='JUM TSANI'!D5 -> Blu'uran, Karang Penang | G5: Halaman | H5: :
A6: Kabupaten | C6: : | D6: ='JUM TSANI'!D6 -> Sampang
A8: Tanggal (Masehi) | B8: Tanggal (Hijriyah) | C8: No. Kode | D8: No. Bukti | E8: URAIAN | G8: Penerimaan | H8: Pengeluaran | I8: Saldo
G9: (Rp) | H9: (Rp) | I9: (Rp)
A10: 1 | B10: 2 | C10: 3 | D10: 4 | E10: 5 | G10: 6 | H10: 7 | I10: 8
D11: 1 | E11: Saldo Awal Bulan J. Tsani | G11: =if(D11=1,'JUM TSANI'!I23,"") -> 3590000 | I11: =IF(OR(G11<>0,H11<>0),SUM(G$11:G11)-SUM(H$11:H11),0) -> 3590000
E12: SOUND | G12: 6690000 | H12: 8820000 | I12: =IF(OR(G12<>0,H12<>0),SUM(G$11:G12)-SUM(H$11:H12),0) -> 1460000
E13: PANGGUNG | G13: 500000 | H13: 635000 | I13: =IF(OR(G13<>0,H13<>0),SUM(G$11:G13)-SUM(H$11:H13),0) -> 1325000
E14: TENDA | G14: 13548000 | H14: 7275000 | I14: =IF(OR(G14<>0,H14<>0),SUM(G$11:G14)-SUM(H$11:H14),0) -> 7598000
E15: KURSI | G15: 1850000 | H15: 2450000 | I15: =IF(OR(G15<>0,H15<>0),SUM(G$11:G15)-SUM(H$11:H15),0) -> 6998000
E16: PERBAIKAN PESANTREN | I16: =IF(OR(G16<>0,H16<>0),SUM(G$11:G16)-SUM(H$11:H16),0) -> 0
E17: DI SETOR KE MADRASAH UNTUK BIAYA IMDA 1 | I17: =IF(OR(G17<>0,H17<>0),SUM(G$11:G17)-SUM(H$11:H17),0) -> 0
E18: DI SETOR KE YAYASAN | H18: 6930000 | I18: =IF(OR(G18<>0,H18<>0),SUM(G$11:G18)-SUM(H$11:H18),0) -> 68000
E19: =IFERROR(VLOOKUP(C19,#REF!,2)," ") | I19: =IF(OR(G19<>0,H19<>0),SUM(G$11:G19)-SUM(H$11:H19),0) -> 0
E20: =IFERROR(VLOOKUP(C20,#REF!,2)," ") | I20: =IF(OR(G20<>0,H20<>0),SUM(G$11:G20)-SUM(H$11:H20),0) -> 0
I21: =IF(OR(G21<>0,H21<>0),SUM(G$11:G21)-SUM(H$11:H21),0) -> 0
E22: =IFERROR(VLOOKUP(C22,#REF!,2)," ") | I22: =IF(OR(G22<>0,H22<>0),SUM(G$11:G22)-SUM(H$11:H22),0) -> 0
E23: =IFERROR(VLOOKUP(C23,#REF!,2)," ") | I23: =IF(OR(G23<>0,H23<>0),SUM(G$11:G23)-SUM(H$11:H23),0) -> 0
E24: =IFERROR(VLOOKUP(C24,#REF!,2)," ") | I24: =IF(OR(G24<>0,H24<>0),SUM(G$11:G24)-SUM(H$11:H24),0) -> 0
E25: =IFERROR(VLOOKUP(C25,#REF!,2)," ") | I25: =IF(OR(G25<>0,H25<>0),SUM(G$11:G25)-SUM(H$11:H25),0) -> 0
E26: =IFERROR(VLOOKUP(C26,#REF!,2)," ") | I26: =IF(OR(G26<>0,H26<>0),SUM(G$11:G26)-SUM(H$11:H26),0) -> 0
E27: =IFERROR(VLOOKUP(C27,#REF!,2)," ") | I27: =IF(OR(G27<>0,H27<>0),SUM(G$11:G27)-SUM(H$11:H27),0) -> 0
E28: =IFERROR(VLOOKUP(C28,#REF!,2)," ") | I28: =IF(OR(G28<>0,H28<>0),SUM(G$11:G28)-SUM(H$11:H28),0) -> 0
G29: =SUM(G11:G28) -> 26178000 | H29: =SUM(H11:H28) -> 26110000 | I29: =G29-H29 -> 68000
A30: Pada hari ................ tanggal ........... bulan.......... tahun .................. Buku Kas Umum ditutup dengan keadaan sebagai berikut :
A31: Saldo Buku Kas Umum | F31: =+I29 -> 68000
A32: Terdiri dari :
A33: Saldo Kas Tunai (isi sendiri)
A34: Saldo Bank | E34: =I29-E33 -> 68000
A35: Jumlah | F35: =SUM(E33:E34) -> 68000
A37: Mengetahui, | G37: Sampang, ..........................................
A38: ='JUM TSANI'!A32 -> Ketua Yayasan | G38: ='JUM TSANI'!G32 -> Bendahara
A43: ='JUM TSANI'!A37 -> K. KHOIRUS SHOLEH | G43: ='JUM TSANI'!G37 -> ..............................................
A57: BUKU KAS UMUM
A59: Nama Sekolah | D59: :
A60: Desa/Kecamatan | D60: :
A61: Kabupaten | D61: : Sleman | H61: Halaman :
A63: Tanggal | C63: No. Kode | D63: No. Bukti | E63: URAIAN | G63: Penerimaan | H63: Pengeluaran | I63: Saldo
...

Sheet SYABAN
A2: BUKU KAS UMUM
A4: Nama Madrasah | C4: : | D4: =RAJAB!D4 | G4: Bulan | H4: : Sya'ban
A5: Desa/Kecamatan | C5: : | D5: =RAJAB!D5 -> Blu'uran, Karang Penang | G5: Halaman | H5: :
A6: Kabupaten | C6: : | D6: =RAJAB!D6 -> Sampang
A8: Tanggal (Masehi) | B8: Tanggal (Hijriyah) | C8: No. Kode | D8: No. Bukti | E8: URAIAN | G8: Penerimaan | H8: Pengeluaran | I8: Saldo
G9: (Rp) | H9: (Rp) | I9: (Rp)
A10: 1 | B10: 2 | C10: 3 | D10: 4 | E10: 5 | G10: 6 | H10: 7 | I10: 8
D11: 1 | E11: Saldo Awal Bulan Rajab | G11: =if(D11=1,RAJAB!I29,"") -> 68000 | I11: =IF(OR(G11<>0,H11<>0),SUM(G$11:G11)-SUM(H$11:H11),0) -> 68000
E12: SOUND | I12: =IF(OR(G12<>0,H12<>0),SUM(G$11:G12)-SUM(H$11:H12),0) -> 0
E13: PANGGUNG | G13: 17567000 | H13: 10590000 | I13: =IF(OR(G13<>0,H13<>0),SUM(G$11:G13)-SUM(H$11:H13),0) -> 7045000
E14: TENDA | G14: 26893000 | H14: 21488000 | I14: =IF(OR(G14<>0,H14<>0),SUM(G$11:G14)-SUM(H$11:H14),0) -> 12450000
E15: KURSI | G15: 1600000 | H15: 1020000 | I15: =IF(OR(G15<>0,H15<>0),SUM(G$11:G15)-SUM(H$11:H15),0) -> 13030000
E16: PERBAIKAN PESANTREN | I16: =IF(OR(G16<>0,H16<>0),SUM(G$11:G16)-SUM(H$11:H16),0) -> 0
E17: DI SETOR KE MADRASAH UNTUK BIAYA IMDA 1 | I17: =IF(OR(G17<>0,H17<>0),SUM(G$11:G17)-SUM(H$11:H17),0) -> 0
E18: DI SETOR KE YAYASAN | H18: 8010000 | I18: =IF(OR(G18<>0,H18<>0),SUM(G$11:G18)-SUM(H$11:H18),0) -> 5020000
E19: =IFERROR(VLOOKUP(C19,#REF!,2)," ") | I19: =IF(OR(G19<>0,H19<>0),SUM(G$11:G19)-SUM(H$11:H19),0) -> 0
E20: =IFERROR(VLOOKUP(C20,#REF!,2)," ") | I20: =IF(OR(G20<>0,H20<>0),SUM(G$11:G20)-SUM(H$11:H20),0) -> 0
E21: =IFERROR(VLOOKUP(C21,#REF!,2)," ") | I21: =IF(OR(G21<>0,H21<>0),SUM(G$11:G21)-SUM(H$11:H21),0) -> 0
E22: =IFERROR(VLOOKUP(C22,#REF!,2)," ") | I22: =IF(OR(G22<>0,H22<>0),SUM(G$11:G22)-SUM(H$11:H22),0) -> 0
E23: =IFERROR(VLOOKUP(C23,#REF!,2)," ") | I23: =IF(OR(G23<>0,H23<>0),SUM(G$11:G23)-SUM(H$11:H23),0) -> 0
E24: =IFERROR(VLOOKUP(C24,#REF!,2)," ") | I24: =IF(OR(G24<>0,H24<>0),SUM(G$11:G24)-SUM(H$11:H24),0) -> 0
E25: =IFERROR(VLOOKUP(C25,#REF!,2)," ") | I25: =IF(OR(G25<>0,H25<>0),SUM(G$11:G25)-SUM(H$11:H25),0) -> 0
E26: =IFERROR(VLOOKUP(C26,#REF!,2)," ") | I26: =IF(OR(G26<>0,H26<>0),SUM(G$11:G26)-SUM(H$11:H26),0) -> 0
E27: =IFERROR(VLOOKUP(C27,#REF!,2)," ") | I27: =IF(OR(G27<>0,H27<>0),SUM(G$11:G27)-SUM(H$11:H27),0) -> 0
E28: =IFERROR(VLOOKUP(C28,#REF!,2)," ") | I28: =IF(OR(G28<>0,H28<>0),SUM(G$11:G28)-SUM(H$11:H28),0) -> 0
G29: =SUM(G11:G28) -> 46128000 | H29: =SUM(H11:H28) -> 41108000 | I29: =G29-H29 -> 5020000
A30: Pada hari ................ tanggal ........... bulan.......... tahun .................. Buku Kas Umum ditutup dengan keadaan sebagai berikut :
A31: Saldo Buku Kas Umum | F31: =+I29 -> 5020000
A32: Terdiri dari :
A33: Saldo Kas Tunai (isi sendiri)
A34: Saldo Bank | E34: =I29-E33 -> 5020000
A35: Jumlah | F35: =SUM(E33:E34) -> 5020000
A37: Mengetahui, | G37: Sampang, .......................................................
A38: =RAJAB!A38 -> Ketua Yayasan | G38: =RAJAB!G38 -> Bendahara
A43: =RAJAB!A43 -> K. KHOIRUS SHOLEH | G43: =RAJAB!G43 -> ..............................................
A57: BUKU KAS UMUM
A59: Nama Sekolah | D59: :
A60: Desa/Kecamatan | D60: :
A61: Kabupaten | D61: : Sleman | H61: Halaman :
A63: Tanggal | C63: No. Kode | D63: No. Bukti | E63: URAIAN | G63: Penerimaan | H63: Pengeluaran | I63: Saldo
...

Sheet RAMADHAN
A2: BUKU KAS UMUM
A4: Nama Madrasah | C4: : | D4: =SYABAN!D4 | G4: Bulan | H4: : Ramadhan
A5: Desa/Kecamatan | C5: : | D5: =SYABAN!D5 -> Blu'uran, Karang Penang | G5: Halaman | H5: :
A6: Kabupaten | C6: : | D6: =SYABAN!D6 -> Sampang
A8: Tanggal (Masehi) | B8: Tanggal (Hijriyah) | C8: No. Kode | D8: No. Bukti | E8: URAIAN | G8: Penerimaan | H8: Pengeluaran | I8: Saldo
G9: (Rp) | H9: (Rp) | I9: (Rp)
A10: 1 | B10: 2 | C10: 3 | D10: 4 | E10: 5 | G10: 6 | H10: 7 | I10: 8
D11: 1 | E11: Saldo Awal Bulan Sya'ban | G11: =if(D11=1,SYABAN!I29,"") -> 5020000 | I11: =IF(OR(G11<>0,H11<>0),SUM(G$11:G11)-SUM(H$11:H11),0) -> 5020000
E12: SOUND | I12: =IF(OR(G12<>0,H12<>0),SUM(G$11:G12)-SUM(H$11:H12),0) -> 0
E13: PANGGUNG | I13: =IF(OR(G13<>0,H13<>0),SUM(G$11:G13)-SUM(H$11:H13),0) -> 0
E14: TENDA | I14: =IF(OR(G14<>0,H14<>0),SUM(G$11:G14)-SUM(H$11:H14),0) -> 0
E15: KURSI | I15: =IF(OR(G15<>0,H15<>0),SUM(G$11:G15)-SUM(H$11:H15),0) -> 0
E16: DI SETOR KE MADRASAH UNTUK BIAYA IMDA 1 | I16: =IF(OR(G16<>0,H16<>0),SUM(G$11:G16)-SUM(H$11:H16),0) -> 0
E17: DI SETOR KE YAYASAN | I17: =IF(OR(G17<>0,H17<>0),SUM(G$11:G17)-SUM(H$11:H17),0) -> 0
I18: =IF(OR(G18<>0,H18<>0),SUM(G$11:G18)-SUM(H$11:H18),0) -> 0
I19: =IF(OR(G19<>0,H19<>0),SUM(G$11:G19)-SUM(H$11:H19),0) -> 0
I20: =IF(OR(G20<>0,H20<>0),SUM(G$11:G20)-SUM(H$11:H20),0) -> 0
I21: =IF(OR(G21<>0,H21<>0),SUM(G$11:G21)-SUM(H$11:H21),0) -> 0
I22: =IF(OR(G22<>0,H22<>0),SUM(G$11:G22)-SUM(H$11:H22),0) -> 0
I23: =IF(OR(G23<>0,H23<>0),SUM(G$11:G23)-SUM(H$11:H23),0) -> 0
E24: =IFERROR(VLOOKUP(C24,#REF!,2)," ") | I24: =IF(OR(G24<>0,H24<>0),SUM(G$11:G24)-SUM(H$11:H24),0) -> 0
E25: =IFERROR(VLOOKUP(C25,#REF!,2)," ") | I25: =IF(OR(G25<>0,H25<>0),SUM(G$11:G25)-SUM(H$11:H25),0) -> 0
E26: =IFERROR(VLOOKUP(C26,#REF!,2)," ") | I26: =IF(OR(G26<>0,H26<>0),SUM(G$11:G26)-SUM(H$11:H26),0) -> 0
E27: =IFERROR(VLOOKUP(C27,#REF!,2)," ") | I27: =IF(OR(G27<>0,H27<>0),SUM(G$11:G27)-SUM(H$11:H27),0) -> 0
E28: =IFERROR(VLOOKUP(C28,#REF!,2)," ") | I28: =IF(OR(G28<>0,H28<>0),SUM(G$11:G28)-SUM(H$11:H28),0) -> 0
E29: =IFERROR(VLOOKUP(C29,#REF!,2)," ") | I29: =IF(OR(G29<>0,H29<>0),SUM(G$11:G29)-SUM(H$11:H29),0) -> 0
G30: =SUM(G11:G29) -> 5020000 | H30: =SUM(H11:H29) -> 0 | I30: =G30-H30 -> 5020000
A31: Pada hari ................ tanggal ........... bulan.......... tahun .................. Buku Kas Umum ditutup dengan keadaan sebagai berikut :
A32: Saldo Buku Kas Umum | F32: =+I30 -> 5020000
A33: Terdiri dari :
A34: Saldo Kas Tunai (isi sendiri)
A35: Saldo Bank | E35: =I30-E34 -> 5020000
A36: Jumlah | F36: =SUM(E34:E35) -> 5020000
A38: Mengetahui, | G38: Sampang, .................................................
A39: =SYABAN!A38 -> Ketua Yayasan | G39: =SYABAN!G38 -> Bendahara
A44: =SYABAN!A43 -> K. KHOIRUS SHOLEH | G44: =SYABAN!G43 -> ..............................................
A58: BUKU KAS UMUM
A60: Nama Sekolah | D60: :
A61: Desa/Kecamatan | D61: :
A62: Kabupaten | D62: : Sleman | H62: Halaman :
...
