Workbook

Sheet TOTAL
A1: TOTAL BUKU KAS UMUM
A3: Nama Madrasah | C3: : | D3: Yayasan | G3: Bulan | H3: : Dzulqo'dah
A4: Desa/Kecamatan | C4: : | D4: =SYAWAL!D4 -> Yayasan | G4: Halaman | H4: :
A5: Kabupaten | C5: : | D5: =SYAWAL!D5 -> Blu'uran, Karang Penang
A7: Tanggal (Masehi) | B7: Tanggal (Hijriyah) | C7: No. Kode | D7: No. Bukti | E7: URAIAN | G7: Penerimaan | H7: Pengeluaran | I7: Saldo
G8: (Rp) | H8: (Rp) | I8: (Rp)
A9: 1 | B9: 2 | C9: 3 | D9: 4 | E9: 5 | G9: 6 | H9: 7 | I9: 8
E10: Bulan Syawal | G10: =SYAWAL!H42 -> 322000 | H10: =SYAWAL!I42 -> 395000 | I10: =IF(OR(G10<>0,H10<>0),SUM(G10:G$11)-SUM(H10:H$11),0) -> -68000
E11: Bulan Dzulqa'dah | G11: =DZULQADAH!G30 -> 220000 | H11: =DZULQADAH!H30 -> 215000 | I11: =IF(OR(G11<>0,H11<>0),SUM(G11:G$11)-SUM(H11:H$11),0) -> 5000
E12: Bulan Dzulhijjah | G12: =DZULHIJJAH!G29 -> 0 | H12: =DZULHIJJAH!H29 -> 0 | I12: =IF(OR(G12<>0,H12<>0),SUM(G12:G$11)-SUM(H12:H$11),0) -> 0
E13: Bulan Shafar | G13: =MOHARROM!G29 -> 0 | H13: =MOHARROM!H29 -> 0 | I13: =IF(OR(G13<>0,H13<>0),SUM(G13:G$11)-SUM(H13:H$11),0) -> 0
E14: Bulan Muharrom | G14: =SHAFAR!G29 -> 0 | H14: =SHAFAR!H29 -> 0 | I14: =IF(OR(G14<>0,H14<>0),SUM(G14:G$11)-SUM(H14:H$11),0) -> 0
E15: Bulan Rabiul Awal | G15: ='RABIUL AWAL'!G37 -> 0 | H15: ='RABIUL AWAL'!H37 -> 0 | I15: =IF(OR(G15<>0,H15<>0),SUM(G15:G$11)-SUM(H15:H$11),0) -> 0
E16: Bulan Rabiul Tsani | G16: ='RABIUL TSANI'!G29 -> 0 | H16: ='RABIUL TSANI'!H29 -> 0 | I16: =IF(OR(G16<>0,H16<>0),SUM(G16:G$11)-SUM(H16:H$11),0) -> 0
E17: Bulan Jum Ula | G17: ='JUM ULA'!G29 -> 0 | H17: ='JUM ULA'!H29 -> 0 | I17: =IF(OR(G17<>0,H17<>0),SUM(G17:G$11)-SUM(H17:H$11),0) -> 0
E18: Bulan Jum Tsani | G18: ='JUM TSANI'!G29 -> 1050000 | H18: ='JUM TSANI'!H29 -> 841000 | I18: =IF(OR(G18<>0,H18<>0),SUM(G18:G$11)-SUM(H18:H$11),0) -> 214000
E19: Bulan Rajab | G19: =RAJAB!G29 -> 0 | H19: =RAJAB!H29 -> 0 | I19: =IF(OR(G19<>0,H19<>0),SUM(G19:G$11)-SUM(H19:H$11),0) -> 0
E20: Bulan Sya'ban | G20: =SYABAN!G29 -> 0 | H20: =SYABAN!H29 -> 0 | I20: =IF(OR(G20<>0,H20<>0),SUM(G20:G$11)-SUM(H20:H$11),0) -> 0
E21: Bulan Ramadhan | G21: =RAMADHAN!G30 -> 0 | H21: =RAMADHAN!H30 -> 0 | I21: =IF(OR(G21<>0,H21<>0),SUM(G21:G$11)-SUM(H21:H$11),0) -> 0
G22: =SUM(G10:G21) -> 1592000 | H22: =SUM(H10:H21) -> 1451000 | I22: =G22-H22 -> 141000
A23: Pada hari ............. tanggal .......... Dzulqa'dah 1445, Buku Kas Umum ditutup dengan keadaan sebagai berikut :
A24: Saldo Buku Kas Umum | F24: =+I22 -> 141000
A25: Terdiri dari :
A26: Saldo Kas Tunai (isi sendiri)
A27: Saldo Bank | E27: =I22-E26 -> 141000
A28: Jumlah | F28: =SUM(E26:E27) -> 141000
A30: Mengetahui, | G30: Sampang, .............................................
A31: Ketua Yayasan | G31: Bendahara Yayasan
A32: K. KHOIRUS SHOLEH | G32: .............................

Sheet SYAWAL
A2: BUKU KAS UMUM
A4: Nama Madrasah | C4: : | D4: Yayasan | H4: Bulan | I4: : Syawal
A5: Desa/Kecamatan | C5: : | D5: Blu'uran, Karang Penang | H5: Halaman | I5: :
A6: Kabupaten | C6: : | D6: Sampang
A8: Tanggal (Masehi) | B8: Tanggal (Hijriyah) | C8: No. Kode | D8: No. Bukti | E8: URAIAN | G8: SUMBER DANA | H8: Penerimaan | I8: Pengeluaran | J8: Saldo
H9: (Rp) | I9: (Rp) | J9: (Rp)
A10: 1 | B10: 2 | C10: 3 | D10: 4 | E10: 5 | G10: 6 | H10: 7 | I10: 8 | J10: 9
G11: PSB | H11: 322000 | J11: =IF(OR(H11<>0,I11<>0),SUM(H$11:H11)-SUM(I$11:I11),0) -> 322000
E12: Papan Nama | I12: 60000 | J12: =IF(OR(H12<>0,I12<>0),SUM(H$11:H12)-SUM(I$11:I12),0) -> 262000
E13: Buku Paperline | I13: 19000 | J13: =IF(OR(H13<>0,I13<>0),SUM(H$11:H13)-SUM(I$11:I13),0) -> 243000
E14: Alat Batas santri | I14: 50000 | J14: =IF(OR(H14<>0,I14<>0),SUM(H$11:H14)-SUM(I$11:I14),0) -> 193000
E15: Lampu | I15: 216000 | J15: =IF(OR(H15<>0,I15<>0),SUM(H$11:H15)-SUM(I$11:I15),0) -> -23000
E16: lain lain | I16: 50000 | J16: =IF(OR(H16<>0,I16<>0),SUM(H$11:H16)-SUM(I$11:I16),0) -> -73000
J17: =IF(OR(H17<>0,I17<>0),SUM(H$11:H17)-SUM(I$11:I17),0) -> 0
J18: =IF(OR(H18<>0,I18<>0),SUM(H$11:H18)-SUM(I$11:I18),0) -> 0
J19: =IF(OR(H19<>0,I19<>0),SUM(H$11:H19)-SUM(I$11:I19),0) -> 0
J20: =IF(OR(H20<>0,I20<>0),SUM(H$11:H20)-SUM(I$11:I20),0) -> 0
J21: =IF(OR(H21<>0,I21<>0),SUM(H$11:H21)-SUM(I$11:I21),0) -> 0
J22: =IF(OR(H22<>0,I22<>0),SUM(H$11:H22)-SUM(I$11:I22),0) -> 0
J23: =IF(OR(H23<>0,I23<>0),SUM(H$11:H23)-SUM(I$11:I23),0) -> 0
J24: =IF(OR(H24<>0,I24<>0),SUM(H$11:H24)-SUM(I$11:I24),0) -> 0
J25: =IF(OR(H25<>0,I25<>0),SUM(H$11:H25)-SUM(I$11:I25),0) -> 0
J26: =IF(OR(H26<>0,I26<>0),SUM(H$11:H26)-SUM(I$11:I26),0) -> 0
J27: =IF(OR(H27<>0,I27<>0),SUM(H$11:H27)-SUM(I$11:I27),0) -> 0
J28: =IF(OR(H28<>0,I28<>0),SUM(H$11:H28)-SUM(I$11:I28),0) -> 0
... J40: =IF(OR(H40<>0,I40<>0),SUM(H$11:H40)-SUM(I$11:I40),0) -> 0
E41: =IFERROR(VLOOKUP(C41,#REF!,2)," ") | J41: =IF(OR(H41<>0,I41<>0),SUM(H$11:H41)-SUM(I$11:I41),0) -> 0
H42: =SUM(H11:H41) -> 322000 | I42: =SUM(I11:I41) -> 395000 | J42: =H42-I42 -> -73000
A43: Pada hari ................ tanggal ........... bulan.......... tahun .................. Buku Kas Umum ditutup dengan keadaan sebagai berikut :
A44: Saldo Buku Kas Umum | F44: =+J42 -> -73000
A45: Terdiri dari :
A46: Saldo Kas Tunai (isi sendiri)
A47: Saldo Bank | E47: =J42-E46 -> -73000
A48: Jumlah | F48: =SUM(E46:E47) -> -73000
A50: Mengetahui, | I50: Sampang, .................................
A51: Ketua Yayasan | I51: Bendahara
A56: K. KHOIRUS SHOLEH | I56: .....................................

Sheet DZULQADAH
A2: BUKU KAS UMUM
A4: Nama Madrasah | C4: : | G4: Bulan | H4: : Dzulqo'dah
A5: Desa/Kecamatan | C5: : | D5: =SYAWAL!D5 -> Blu'uran, Karang Penang | G5: Halaman | H5: :
A6: Kabupaten | C6: : | D6: =SYAWAL!D6 -> Sampang
A8: Tanggal (Masehi) | B8: Tanggal (Hijriyah) | C8: No. Kode | D8: No. Bukti | E8: URAIAN | G8: Penerimaan | H8: Pengeluaran | I8: Saldo
G9: (Rp) | H9: (Rp) | I9: (Rp)
A10: 1 | B10: 2 | C10: 3 | D10: 4 | E10: 5 | G10: 6 | H10: 7 | I10: 8
E11: PSB / Uang gedung, surat izin | G11: 220000 | I11: =IF(OR(G11<>0,H11<>0),SUM(G$11:G11)-SUM(H$11:H11),0) -> 220000
E12: Sapu lidi 4 biji | H12: 48000 | I12: =IF(OR(G12<>0,H12<>0),SUM(G$11:G12)-SUM(H$11:H12),0) -> 172000
E13: Sapu lantai 5 | H13: 155000 | I13: =IF(OR(G13<>0,H13<>0),SUM(G$11:G13)-SUM(H$11:H13),0) -> 17000
E14: Jikrak | H14: 12000 | I14: =IF(OR(G14<>0,H14<>0),SUM(G$11:G14)-SUM(H$11:H14),0) -> 5000
I15: =IF(OR(G15<>0,H15<>0),SUM(G$11:G15)-SUM(H$11:H15),0) -> 0
I16: =IF(OR(G16<>0,H16<>0),SUM(G$11:G16)-SUM(H$11:H16),0) -> 0
I17: =IF(OR(G17<>0,H17<>0),SUM(G$11:G17)-SUM(H$11:H17),0) -> 0
I18: =IF(OR(G18<>0,H18<>0),SUM(G$11:G18)-SUM(H$11:H18),0) -> 0
I19: =IF(OR(G19<>0,H19<>0),SUM(G$11:G19)-SUM(H$11:H19),0) -> 0
I20: =IF(OR(G20<>0,H20<>0),SUM(G$11:G20)-SUM(H$11:H20),0) -> 0
I21: =IF(OR(G21<>0,H21<>0),SUM(G$11:G21)-SUM(H$11:H21),0) -> 0
I22: =IF(OR(G22<>0,H22<>0),SUM(G$11:G22)-SUM(H$11:H22),0) -> 0
I23: =IF(OR(G23<>0,H23<>0),SUM(G$11:G23)-SUM(H$11:H23),0) -> 0
I24: =IF(OR(G24<>0,H24<>0),SUM(G$11:G24)-SUM(H$11:H24),0) -> 0
E25: =IFERROR(VLOOKUP(C25,#REF!,2)," ") | I25: =IF(OR(G25<>0,H25<>0),SUM(G$11:G25)-SUM(H$11:H25),0) -> 0
E26: =IFERROR(VLOOKUP(C26,#REF!,2)," ") | I26: =IF(OR(G26<>0,H26<>0),SUM(G$11:G26)-SUM(H$11:H26),0) -> 0
E27: =IFERROR(VLOOKUP(C27,#REF!,2)," ") | I27: =IF(OR(G27<>0,H27<>0),SUM(G$11:G27)-SUM(H$11:H27),0) -> 0
E28: =IFERROR(VLOOKUP(C28,#REF!,2)," ") | I28: =IF(OR(G28<>0,H28<>0),SUM(G$11:G28)-SUM(H$11:H28),0) -> 0
E29: =IFERROR(VLOOKUP(C29,#REF!,2)," ") | I29: =IF(OR(G29<>0,H29<>0),SUM(G$11:G29)-SUM(H$11:H29),0) -> 0
G30: =SUM(G11:G29) -> 220000 | H30: =SUM(H11:H29) -> 215000 | I30: =G30-H30 -> 5000
A31: Pada hari ................ tanggal ........... bulan.......... tahun .................. Buku Kas Umum ditutup dengan keadaan sebagai berikut :
A32: Saldo Buku Kas Umum | F32: =+I30 -> 5000
A33: Terdiri dari :
A34: Saldo Kas Tunai (isi sendiri)
A35: Saldo Bank | E35: =I30-E34 -> 5000
A36: Jumlah | F36: =SUM(E34:E35) -> 5000
A38: Mengetahui, | G38: Sampang, ......................................1446
A39: Ketua Yayasan | G39: Bendahara
A44: K. KHOIRUS SHOLEH | G44: ..............................................
A58: BUKU KAS UMUM
A60: Nama Sekolah | D60: :
A61: Desa/Kecamatan | D61: :
A62: Kabupaten | D62: : Sleman | H62: Halaman :
...

Sheet MOHARROM
A2: BUKU KAS UMUM
A4: Nama Madrasah | C4: : | D4: =SHAFAR!D4 | G4: Bulan | H4: : Shafar
A5: Desa/Kecamatan | C5: : | D5: =SHAFAR!D5 -> Blu'uran, Karang Penang | G5: Halaman | H5: :
A6: Kabupaten | C6: : | D6: =SHAFAR!D6 -> Sampang
A8: Tanggal (Masehi) | B8: Tanggal (Hijriyah) | C8: No. Kode | D8: No. Bukti | E8: URAIAN | G8: Penerimaan | H8: Pengeluaran | I8: Saldo
G9: (Rp) | H9: (Rp) | I9: (Rp)
A10: 1 | B10: 2 | C10: 3 | D10: 4 | E10: 5 | G10: 6 | H10: 7 | I10: 8
E11: Saldo Bulan Dzulhijjah | G11: =if(D11=1,DZULHIJJAH!I29,"") | I11: =IF(OR(G11<>0,H11<>0),SUM(G$11:G11)-SUM(H$11:H11),0) -> 0
I12: =IF(OR(G12<>0,H12<>0),SUM(G$11:G12)-SUM(H$11:H12),0) -> 0
I13: =IF(OR(G13<>0,H13<>0),SUM(G$11:G13)-SUM(H$11:H13),0) -> 0
I14: =IF(OR(G14<>0,H14<>0),SUM(G$11:G14)-SUM(H$11:H14),0) -> 0
I15: =IF(OR(G15<>0,H15<>0),SUM(G$11:G15)-SUM(H$11:H15),0) -> 0
E16: =IFERROR(VLOOKUP(C16,#REF!,2)," ") | I16: =IF(OR(G16<>0,H16<>0),SUM(G$11:G16)-SUM(H$11:H16),0) -> 0
E17: =IFERROR(VLOOKUP(C17,#REF!,2)," ") | I17: =IF(OR(G17<>0,H17<>0),SUM(G$11:G17)-SUM(H$11:H17),0) -> 0
E18: =IFERROR(VLOOKUP(C18,#REF!,2)," ") | I18: =IF(OR(G18<>0,H18<>0),SUM(G$11:G18)-SUM(H$11:H18),0) -> 0
E19: =IFERROR(VLOOKUP(C19,#REF!,2)," ") | I19: =IF(OR(G19<>0,H19<>0),SUM(G$11:G19)-SUM(H$11:H19),0) -> 0
E20: =IFERROR(VLOOKUP(C20,#REF!,2)," ") | I20: =IF(OR(G20<>0,H20<>0),SUM(G$11:G20)-SUM(H$11:H20),0) -> 0
E21: =IFERROR(VLOOKUP(C21,#REF!,2)," ") | I21: =IF(OR(G21<>0,H21<>0),SUM(G$11:G21)-SUM(H$11:H21),0) -> 0
E22: =IFERROR(VLOOKUP(C22,#REF!,2)," ") | I22: =IF(OR(G22<>0,H22<>0),SUM(G$11:G22)-SUM(H$11:H22),0) -> 0
E23: =IFERROR(VLOOKUP(C23,#REF!,2)," ") | I23: =IF(OR(G23<>0,H23<>0),SUM(G$11:G23)-SUM(H$11:H23),0) -> 0
E24: =IFERROR(VLOOKUP(C24,#REF!,2)," ") | I24: =IF(OR(G24<>0,H24<>0),SUM(G$11:G24)-SUM(H$11:H24),0) -> 0
E25: =IFERROR(VLOOKUP(C25,#REF!,2)," ") | I25: =IF(OR(G25<>0,H25<>0),SUM(G$11:G25)-SUM(H$11:H25),0) -> 0
E26: =IFERROR(VLOOKUP(C26,#REF!,2)," ") | I26: =IF(OR(G26<>0,H26<>0),SUM(G$11:G26)-SUM(H$11:H26),0) -> 0
E27: =IFERROR(VLOOKUP(C27,#REF!,2)," ") | I27: =IF(OR(G27<>0,H27<>0),SUM(G$11:G27)-SUM(H$11:H27),0) -> 0
E28: =IFERROR(VLOOKUP(C28,#REF!,2)," ") | I28: =IF(OR(G28<>0,H28<>0),SUM(G$11:G28)-SUM(H$11:H28),0) -> 0
G29: =SUM(G11:G28) -> 0 | H29: =SUM(H11:H28) -> 0 | I29: =G29-H29 -> 0
A30: Pada hari ................ tanggal ........... bulan.......... tahun .................. Buku Kas Umum ditutup dengan keadaan sebagai berikut :
A31: Saldo Buku Kas Umum | F31: =+I29 -> 0
A32: Terdiri dari :
A33: Saldo Kas Tunai (isi sendiri)
A34: Saldo Bank | E34: =I29-E33 -> 0
A35: Jumlah | F35: =SUM(E33:E34) -> 0
A37: Mengetahui, | G37: Sampang,.........................................
A38: =SHAFAR!A38 -> Ketua Yayasan | G38: =SHAFAR!G38 -> Bendahara
A43: =SHAFAR!A43 -> K. KHOIRUS SHOLEH | G43: =SHAFAR!G43 -> ..............................................
A57: BUKU KAS UMUM
A59: Nama Sekolah | D59: :
A60: Desa/Kecamatan | D60: :
A61: Kabupaten | D61: : Sleman | H61: Halaman :
A63: Tanggal | C63: No. Kode | D63: No. Bukti | E63: URAIAN | G63: Penerimaan | H63: Pengeluaran | I63: Saldo
...

Sheet DZULHIJJAH
A2: BUKU KAS UMUM
A4: Nama Madrasah | C4: : | D4: =DZULQADAH!D4 | G4: Bulan | H4: : Dzulhijjah
A5: Desa/Kecamatan | C5: : | D5: =DZULQADAH!D5 -> Blu'uran, Karang Penang | G5: Halaman | H5: :
A6: Kabupaten | C6: : | D6: =DZULQADAH!D6 -> Sampang
A8: Tanggal (Masehi) | B8: Tanggal (Hijriyah) | C8: No. Kode | D8: No. Bukti | E8: URAIAN | G8: Penerimaan | H8: Pengeluaran | I8: Saldo
G9: (Rp) | H9: (Rp) | I9: (Rp)
A10: 1 | C10: 3 | D10: 4 | E10: 5 | G10: 6 | H10: 7 | I10: 8
E11: Saldo awal bulan Dzul Qo'dah | G11: =if(D11=1,DZULQADAH!I30,"") | I11: =IF(OR(G11<>0,H11<>0),SUM(G$11:G11)-SUM(H$11:H11),0) -> 0
I12: =IF(OR(G12<>0,H12<>0),SUM(G$11:G12)-SUM(H$11:H12),0) -> 0
I13: =IF(OR(G13<>0,H13<>0),SUM(G$11:G13)-SUM(H$11:H13),0) -> 0
I14: =IF(OR(G14<>0,H14<>0),SUM(G$11:G14)-SUM(H$11:H14),0) -> 0
I15: =IF(OR(G15<>0,H15<>0),SUM(G$11:G15)-SUM(H$11:H15),0) -> 0
I16: =IF(OR(G16<>0,H16<>0),SUM(G$11:G16)-SUM(H$11:H16),0) -> 0
I17: =IF(OR(G17<>0,H17<>0),SUM(G$11:G17)-SUM(H$11:H17),0) -> 0
I18: =IF(OR(G18<>0,H18<>0),SUM(G$11:G18)-SUM(H$11:H18),0) -> 0
I19: =IF(OR(G19<>0,H19<>0),SUM(G$11:G19)-SUM(H$11:H19),0) -> 0
E20: =IFERROR(VLOOKUP(C20,#REF!,2)," ") | I20: =IF(OR(G20<>0,H20<>0),SUM(G$11:G20)-SUM(H$11:H20),0) -> 0
E21: =IFERROR(VLOOKUP(C21,#REF!,2)," ") | I21: =IF(OR(G21<>0,H21<>0),SUM(G$11:G21)-SUM(H$11:H21),0) -> 0
E22: =IFERROR(VLOOKUP(C22,#REF!,2)," ") | I22: =IF(OR(G22<>0,H22<>0),SUM(G$11:G22)-SUM(H$11:H22),0) -> 0
E23: =IFERROR(VLOOKUP(C23,#REF!,2)," ") | I23: =IF(OR(G23<>0,H23<>0),SUM(G$11:G23)-SUM(H$11:H23),0) -> 0
E24: =IFERROR(VLOOKUP(C24,#REF!,2)," ") | I24: =IF(OR(G24<>0,H24<>0),SUM(G$11:G24)-SUM(H$11:H24),0) -> 0
E25: =IFERROR(VLOOKUP(C25,#REF!,2)," ") | I25: =IF(OR(G25<>0,H25<>0),SUM(G$11:G25)-SUM(H$11:H25),0) -> 0
E26: =IFERROR(VLOOKUP(C26,#REF!,2)," ") | I26: =IF(OR(G26<>0,H26<>0),SUM(G$11:G26)-SUM(H$11:H26),0) -> 0
E27: =IFERROR(VLOOKUP(C27,#REF!,2)," ") | I27: =IF(OR(G27<>0,H27<>0),SUM(G$11:G27)-SUM(H$11:H27),0) -> 0
E28: =IFERROR(VLOOKUP(C28,#REF!,2)," ") | I28: =IF(OR(G28<>0,H28<>0),SUM(G$11:G28)-SUM(H$11:H28),0) -> 0
G29: =SUM(G11:G28) -> 0 | H29: =SUM(H11:H28) -> 0 | I29: =G29-H29 -> 0
A30: Pada hari ................ tanggal ........... bulan.......... tahun .................. Buku Kas Umum ditutup dengan keadaan sebagai berikut :
A31: Saldo Buku Kas Umum | F31: =+I29 -> 0
A32: Terdiri dari :
A33: Saldo Kas Tunai (isi sendiri)
A34: Saldo Bank | E34: =I29-E33 -> 0
A35: Jumlah | F35: =SUM(E33:E34) -> 0
A37: Mengetahui, | G37: Sampang,......................................
A38: =DZULQADAH!A39 -> Ketua Yayasan | G38: =DZULQADAH!G39 -> Bendahara
A43: =DZULQADAH!A44 -> K. KHOIRUS SHOLEH | G43: =DZULQADAH!G44 -> ..............................................
A57: BUKU KAS UMUM
A59: Nama Sekolah | D59: :
A60: Desa/Kecamatan | D60: :
A61: Kabupaten | D61: : Sleman | H61: Halaman :
A63: Tanggal | C63: No. Kode | D63: No. Bukti | E63: URAIAN | G63: Penerimaan | H63: Pengeluaran | I63: Saldo
...

Sheet SHAFAR
A2: BUKU KAS UMUM
A4: Nama Madrasah | C4: : | D4: =DZULHIJJAH!D4 | G4: Bulan | H4: : Muharram
A5: Desa/Kecamatan | C5: : | D5: =DZULHIJJAH!D5 -> Blu'uran, Karang Penang | G5: Halaman | H5: :
A6: Kabupaten | C6: : | D6: =DZULHIJJAH!D6 -> Sampang
A8: Tanggal (Masehi) | B8: Tanggal (Hijriyah) | C8: No. Kode | D8: No. Bukti | E8: URAIAN | G8: Penerimaan | H8: Pengeluaran | I8: Saldo
G9: (Rp) | H9: (Rp) | I9: (Rp)
A10: 1 | B10: 2 | C10: 3 | D10: 4 | E10: 5 | G10: 6 | H10: 7 | I10: 8
G11: =if(D11=1,MOHARROM!I29,"") | I11: =IF(OR(G11<>0,H11<>0),SUM(G$11:G11)-SUM(H$11:H11),0) -> 0
I12: =IF(OR(G12<>0,H12<>0),SUM(G$11:G12)-SUM(H$11:H12),0) -> 0
I13: =IF(OR(G13<>0,H13<>0),SUM(G$11:G13)-SUM(H$11:H13),0) -> 0
I14: =IF(OR(G14<>0,H14<>0),SUM(G$11:G14)-SUM(H$11:H14),0) -> 0
I15: =IF(OR(G15<>0,H15<>0),SUM(G$11:G15)-SUM(H$11:H15),0) -> 0
I16: =IF(OR(G16<>0,H16<>0),SUM(G$11:G16)-SUM(H$11:H16),0) -> 0
I17: =IF(OR(G17<>0,H17<>0),SUM(G$11:G17)-SUM(H$11:H17),0) -> 0
I18: =IF(OR(G18<>0,H18<>0),SUM(G$11:G18)-SUM(H$11:H18),0) -> 0
I19: =IF(OR(G19<>0,H19<>0),SUM(G$11:G19)-SUM(H$11:H19),0) -> 0
E20: =IFERROR(VLOOKUP(C20,#REF!,2)," ") | I20: =IF(OR(G20<>0,H20<>0),SUM(G$11:G20)-SUM(H$11:H20),0) -> 0
E21: =IFERROR(VLOOKUP(C21,#REF!,2)," ") | I21: =IF(OR(G21<>0,H21<>0),SUM(G$11:G21)-SUM(H$11:H21),0) -> 0
E22: =IFERROR(VLOOKUP(C22,#REF!,2)," ") | I22: =IF(OR(G22<>0,H22<>0),SUM(G$11:G22)-SUM(H$11:H22),0) -> 0
E23: =IFERROR(VLOOKUP(C23,#REF!,2)," ") | I23: =IF(OR(G23<>0,H23<>0),SUM(G$11:G23)-SUM(H$11:H23),0) -> 0
I24: =IF(OR(G24<>0,H24<>0),SUM(G$11:G24)-SUM(H$11:H24),0) -> 0
E25: =IFERROR(VLOOKUP(C25,#REF!,2)," ") | I25: =IF(OR(G25<>0,H25<>0),SUM(G$11:G25)-SUM(H$11:H25),0) -> 0
E26: =IFERROR(VLOOKUP(C26,#REF!,2)," ") | I26: =IF(OR(G26<>0,H26<>0),SUM(G$11:G26)-SUM(H$11:H26),0) -> 0
E27: =IFERROR(VLOOKUP(C27,#REF!,2)," ") | I27: =IF(OR(G27<>0,H27<>0),SUM(G$11:G27)-SUM(H$11:H27),0) -> 0
E28: =IFERROR(VLOOKUP(C28,#REF!,2)," ") | I28: =IF(OR(G28<>0,H28<>0),SUM(G$11:G28)-SUM(H$11:H28),0) -> 0
G29: =SUM(G11:G28) -> 0 | H29: =SUM(H11:H28) -> 0 | I29: =G29-H29 -> 0
A30: Pada hari ................ tanggal ........... bulan.......... tahun .................. Buku Kas Umum ditutup dengan keadaan sebagai berikut :
A31: Saldo Buku Kas Umum | F31: =+I29 -> 0
A32: Terdiri dari :
A33: Saldo Kas Tunai (isi sendiri)
A34: Saldo Bank | E34: =I29-E33 -> 0
A35: Jumlah | F35: =SUM(E33:E34) -> 0
A37: Mengetahui, | G37: Sampang, ...................................................
A38: =DZULHIJJAH!A38 -> Ketua Yayasan | G38: =DZULHIJJAH!G38 -> Bendahara
A43: =DZULHIJJAH!A43 -> K. KHOIRUS SHOLEH | G43: =DZULHIJJAH!G43 -> ..............................................
A57: BUKU KAS UMUM
A59: Nama Sekolah | D59: :
A60: Desa/Kecamatan | D60: :
A61: Kabupaten | D61: : Sleman | H61: Halaman :
A63: Tanggal | C63: No. Kode | D63: No. Bukti | E63: URAIAN | G63: Penerimaan | H63: Pengeluaran | I63: Saldo
...

Sheet RABIUL AWAL
A2: BUKU KAS UMUM
A4: Nama Madrasah | C4: : | D4: =MOHARROM!D4 | G4: Bulan | H4: : Rabiul Awal
A5: Desa/Kecamatan | C5: : | D5: =MOHARROM!D5 -> Blu'uran, Karang Penang | G5: Halaman | H5: :
A6: Kabupaten | C6: : | D6: =MOHARROM!D6 -> Sampang
A8: Tanggal (Masehi) | B8: Tanggal (Hijriyah) | C8: No. Kode | D8: No. Bukti | E8: URAIAN | G8: Penerimaan | H8: Pengeluaran | I8: Saldo
G9: (Rp) | H9: (Rp) | I9: (Rp)
A10: 1 | B10: 2 | C10: 3 | D10: 4 | E10: 5 | G10: 6 | H10: 7 | I10: 8
E11: Saldo awal Bulan Muharrom | I11: =IF(OR(G11<>0,H11<>0),SUM(G$11:G11)-SUM(H$11:H11),0) -> 0
I12: =IF(OR(G12<>0,H12<>0),SUM(G$11:G12)-SUM(H$11:H12),0) -> 0
I13: =IF(OR(G13<>0,H13<>0),SUM(G$11:G13)-SUM(H$11:H13),0) -> 0
I14: =IF(OR(G14<>0,H14<>0),SUM(G$11:G14)-SUM(H$11:H14),0) -> 0
I15: =IF(OR(G15<>0,H15<>0),SUM(G$11:G15)-SUM(H$11:H15),0) -> 0
I16: =IF(OR(G16<>0,H16<>0),SUM(G$11:G16)-SUM(H$11:H16),0) -> 0
I17: =IF(OR(G17<>0,H17<>0),SUM(G$11:G17)-SUM(H$11:H17),0) -> 0
I18: =IF(OR(G18<>0,H18<>0),SUM(G$11:G18)-SUM(H$11:H18),0) -> 0
I19: =IF(OR(G19<>0,H19<>0),SUM(G$11:G19)-SUM(H$11:H19),0) -> 0
I20: =IF(OR(G20<>0,H20<>0),SUM(G$11:G20)-SUM(H$11:H20),0) -> 0
I21: =IF(OR(G21<>0,H21<>0),SUM(G$11:G21)-SUM(H$11:H21),0) -> 0
I22: =IF(OR(G22<>0,H22<>0),SUM(G$11:G22)-SUM(H$11:H22),0) -> 0
I23: =IF(OR(G23<>0,H23<>0),SUM(G$11:G23)-SUM(H$11:H23),0) -> 0
... I35: =IF(OR(G35<>0,H35<>0),SUM(G$11:G35)-SUM(H$11:H35),0) -> 0
E36: =IFERROR(VLOOKUP(C36,#REF!,2)," ") | I36: =IF(OR(G36<>0,H36<>0),SUM(G$11:G36)-SUM(H$11:H36),0) -> 0
G37: =SUM(G11:G36) -> 0 | H37: =SUM(H11:H36) -> 0 | I37: =G37-H37 -> 0
A38: Pada hari ................ tanggal ........... bulan.......... tahun .................. Buku Kas Umum ditutup dengan keadaan sebagai berikut :
A39: Saldo Buku Kas Umum | F39: =+I37 -> 0
A40: Terdiri dari :
A41: Saldo Kas Tunai (isi sendiri)
A42: Saldo Bank | E42: =I37-E41 -> 0
A43: Jumlah | F43: =SUM(E41:E42) -> 0
A45: Mengetahui, | G45: Sampang, .....................................................
A46: =MOHARROM!A38 -> Ketua Yayasan | G46: =MOHARROM!G38 -> Bendahara
A51: =MOHARROM!A43 -> K. KHOIRUS SHOLEH | G51: =MOHARROM!G43 -> ..............................................
A65: BUKU KAS UMUM
A67: Nama Sekolah | D67: :
A68: Desa/Kecamatan | D68: :
A69: Kabupaten | D69: : Sleman | H69: Halaman :
A71: Tanggal | C71: No. Kode | D71: No. Bukti | E71: URAIAN | G71: Penerimaan | H71: Pengeluaran | I71: Saldo
G72: (Rp) | H72: (Rp) | I72: (Rp)
A73: 1 | C73: 2 | D73: 3 | E73: 4 | G73: 5 | H73: 6 | I73: 7
A74: 02-05-2015 | E74: Saldo bulan yang lalu | G74: =G37 -> 0 | H74: =H37 -> 0 | I74: =I37 -> 0
...

Sheet RABIUL TSANI
A2: BUKU KAS UMUM
A4: Nama Madrasah | C4: : | D4: ='RABIUL AWAL'!D4 | G4: Bulan | H4: : Rabiul Tsani
A5: Desa/Kecamatan | C5: : | D5: ='RABIUL AWAL'!D5 -> Blu'uran, Karang Penang | G5: Halaman | H5: :
A6: Kabupaten | C6: : | D6: ='RABIUL AWAL'!D6 -> Sampang
A8: Tanggal (Masehi) | B8: Tanggal (Hijriyah) | C8: No. Kode | D8: No. Bukti | E8: URAIAN | G8: Penerimaan | H8: Pengeluaran | I8: Saldo
G9: (Rp) | H9: (Rp) | I9: (Rp)
A10: 1 | B10: 2 | C10: 3 | D10: 4 | E10: 5 | G10: 6 | H10: 7 | I10: 8
E11: Saldo Awal Bulan R. Awal | G11: =if(D11=1,'RABIUL AWAL'!I37,"") | I11: =IF(OR(G11<>0,H11<>0),SUM(G$11:G11)-SUM(H$11:H11),0) -> 0
I12: =IF(OR(G12<>0,H12<>0),SUM(G$11:G12)-SUM(H$11:H12),0) -> 0
I13: =IF(OR(G13<>0,H13<>0),SUM(G$11:G13)-SUM(H$11:H13),0) -> 0
I14: =IF(OR(G14<>0,H14<>0),SUM(G$11:G14)-SUM(H$11:H14),0) -> 0
I15: =IF(OR(G15<>0,H15<>0),SUM(G$11:G15)-SUM(H$11:H15),0) -> 0
I16: =IF(OR(G16<>0,H16<>0),SUM(G$11:G16)-SUM(H$11:H16),0) -> 0
I17: =IF(OR(G17<>0,H17<>0),SUM(G$11:G17)-SUM(H$11:H17),0) -> 0
I18: =IF(OR(G18<>0,H18<>0),SUM(G$11:G18)-SUM(H$11:H18),0) -> 0
I19: =IF(OR(G19<>0,H19<>0),SUM(G$11:G19)-SUM(H$11:H19),0) -> 0
E20: =IFERROR(VLOOKUP(C20,#REF!,2)," ") | I20: =IF(OR(G20<>0,H20<>0),SUM(G$11:G20)-SUM(H$11:H20),0) -> 0
E21: =IFERROR(VLOOKUP(C21,#REF!,2)," ") | I21: =IF(OR(G21<>0,H21<>0),SUM(G$11:G21)-SUM(H$11:H21),0) -> 0
E22: =IFERROR(VLOOKUP(C22,#REF!,2)," ") | I22: =IF(OR(G22<>0,H22<>0),SUM(G$11:G22)-SUM(H$11:H22),0) -> 0
E23: =IFERROR(VLOOKUP(C23,#REF!,2)," ") | I23: =IF(OR(G23<>0,H23<>0),SUM(G$11:G23)-SUM(H$11:H23),0) -> 0
E24: =IFERROR(VLOOKUP(C24,#REF!,2)," ") | I24: =IF(OR(G24<>0,H24<>0),SUM(G$11:G24)-SUM(H$11:H24),0) -> 0
E25: =IFERROR(VLOOKUP(C25,#REF!,2)," ") | I25: =IF(OR(G25<>0,H25<>0),SUM(G$11:G25)-SUM(H$11:H25),0) -> 0
E26: =IFERROR(VLOOKUP(C26,#REF!,2)," ") | I26: =IF(OR(G26<>0,H26<>0),SUM(G$11:G26)-SUM(H$11:H26),0) -> 0
E27: =IFERROR(VLOOKUP(C27,#REF!,2)," ") | I27: =IF(OR(G27<>0,H27<>0),SUM(G$11:G27)-SUM(H$11:H27),0) -> 0
E28: =IFERROR(VLOOKUP(C28,#REF!,2)," ") | I28: =IF(OR(G28<>0,H28<>0),SUM(G$11:G28)-SUM(H$11:H28),0) -> 0
G29: =SUM(G11:G28) -> 0 | H29: =SUM(H11:H28) -> 0 | I29: =G29-H29 -> 0
A30: Pada hari ................ tanggal ........... bulan.......... tahun .................. Buku Kas Umum ditutup dengan keadaan sebagai berikut :
A31: Saldo Buku Kas Umum | F31: =+I29 -> 0
A32: Terdiri dari :
A33: Saldo Kas Tunai (isi sendiri)
A34: Saldo Bank | E34: =I29-E33 -> 0
A35: Jumlah | F35: =SUM(E33:E34) -> 0
A37: Mengetahui, | G37: Sampang, .......................................................
A38: ='RABIUL AWAL'!A46 -> Ketua Yayasan | G38: ='RABIUL AWAL'!G46 -> Bendahara
A43: ='RABIUL AWAL'!A51 -> K. KHOIRUS SHOLEH | G43: ='RABIUL AWAL'!G51 -> ..............................................
A57: BUKU KAS UMUM
A59: Nama Sekolah | D59: :
A60: Desa/Kecamatan | D60: :
A61: Kabupaten | D61: : Sleman | H61: Halaman :
A63: Tanggal | C63: No. Kode | D63: No. Bukti | E63: URAIAN | G63: Penerimaan | H63: Pengeluaran | I63: Saldo
...

Sheet JUM ULA
A2: BUKU KAS UMUM
A4: Nama Madrasah | C4: : | D4: ='RABIUL TSANI'!D4 | G4: Bulan | H4: : Jumadal Ula
A5: Desa/Kecamatan | C5: : | D5: ='RABIUL TSANI'!D5 -> Blu'uran, Karang Penang | G5: Halaman | H5: :
A6: Kabupaten | C6: : | D6: ='RABIUL TSANI'!D6 -> Sampang
A8: Tanggal (Masehi) | B8: Tanggal (Hijriyah) | C8: No. Kode | D8: No. Bukti | E8: URAIAN | G8: Penerimaan | H8: Pengeluaran | I8: Saldo
G9: (Rp) | H9: (Rp) | I9: (Rp)
A10: 1 | B10: 2 | C10: 3 | D10: 4 | E10: 5 | G10: 6 | H10: 7 | I10: 8
E11: Saldo Awal Bulan R. Tsani | G11: =if(D11=1,'RABIUL TSANI'!I29,"") | I11: =IF(OR(G11<>0,H11<>0),SUM(G$11:G11)-SUM(H$11:H11),0) -> 0
I12: =IF(OR(G12<>0,H12<>0),SUM(G$11:G12)-SUM(H$11:H12),0) -> 0
I13: =IF(OR(G13<>0,H13<>0),SUM(G$11:G13)-SUM(H$11:H13),0) -> 0
I14: =IF(OR(G14<>0,H14<>0),SUM(G$11:G14)-SUM(H$11:H14),0) -> 0
E15: =IFERROR(VLOOKUP(C15,#REF!,2)," ") | I15: =IF(OR(G15<>0,H15<>0),SUM(G$11:G15)-SUM(H$11:H15),0) -> 0
E16: =IFERROR(VLOOKUP(C16,#REF!,2)," ") | I16: =IF(OR(G16<>0,H16<>0),SUM(G$11:G16)-SUM(H$11:H16),0) -> 0
E17: =IFERROR(VLOOKUP(C17,#REF!,2)," ") | I17: =IF(OR(G17<>0,H17<>0),SUM(G$11:G17)-SUM(H$11:H17),0) -> 0
E18: =IFERROR(VLOOKUP(C18,#REF!,2)," ") | I18: =IF(OR(G18<>0,H18<>0),SUM(G$11:G18)-SUM(H$11:H18),0) -> 0
E19: =IFERROR(VLOOKUP(C19,#REF!,2)," ") | I19: =IF(OR(G19<>0,H19<>0),SUM(G$11:G19)-SUM(H$11:H19),0) -> 0
E20: =IFERROR(VLOOKUP(C20,#REF!,2)," ") | I20: =IF(OR(G20<>0,H20<>0),SUM(G$11:G20)-SUM(H$11:H20),0) -> 0
E21: =IFERROR(VLOOKUP(C21,#REF!,2)," ") | I21: =IF(OR(G21<>0,H21<>0),SUM(G$11:G21)-SUM(H$11:H21),0) -> 0
E22: =IFERROR(VLOOKUP(C22,#REF!,2)," ") | I22: =IF(OR(G22<>0,H22<>0),SUM(G$11:G22)-SUM(H$11:H22),0) -> 0
E23: =IFERROR(VLOOKUP(C23,#REF!,2)," ") | I23: =IF(OR(G23<>0,H23<>0),SUM(G$11:G23)-SUM(H$11:H23),0) -> 0
E24: =IFERROR(VLOOKUP(C24,#REF!,2)," ") | I24: =IF(OR(G24<>0,H24<>0),SUM(G$11:G24)-SUM(H$11:H24),0) -> 0
E25: =IFERROR(VLOOKUP(C25,#REF!,2)," ") | I25: =IF(OR(G25<>0,H25<>0),SUM(G$11:G25)-SUM(H$11:H25),0) -> 0
E26: =IFERROR(VLOOKUP(C26,#REF!,2)," ") | I26: =IF(OR(G26<>0,H26<>0),SUM(G$11:G26)-SUM(H$11:H26),0) -> 0
... E28: =IFERROR(VLOOKUP(C28,#REF!,2)," ") | I28: =IF(OR(G28<>0,H28<>0),SUM(G$11:G28)-SUM(H$11:H28),0) -> 0
G29: =SUM(G11:G28) -> 0 | H29: =SUM(H11:H28) -> 0 | I29: =G29-H29 -> 0
A30: Pada hari ................ tanggal ........... bulan.......... tahun .................. Buku Kas Umum ditutup dengan keadaan sebagai berikut :
A31: Saldo Buku Kas Umum | F31: =+I29 -> 0
A32: Terdiri dari :
A33: Saldo Kas Tunai (isi sendiri)
A34: Saldo Bank | E34: =I29-E33 -> 0
A35: Jumlah | F35: =SUM(E33:E34) -> 0
A37: Mengetahui, | G37: Sampang, .................................................
A38: ='RABIUL TSANI'!A38 -> Ketua Yayasan | G38: ='RABIUL TSANI'!G38 -> Bendahara
A43: ='RABIUL TSANI'!A43 -> K. KHOIRUS SHOLEH | G43: ='RABIUL TSANI'!G43 -> ..............................................
A57: BUKU KAS UMUM
A59: Nama Sekolah | D59: :
A60: Desa/Kecamatan | D60: :
A61: Kabupaten | D61: : Sleman | H61: Halaman :
A63: Tanggal | C63: No. Kode | D63: No. Bukti | E63: URAIAN | G63: Penerimaan | H63: Pengeluaran | I63: Saldo
G64: (Rp) | H64: (Rp) | I64: (Rp)
...

Sheet JUM TSANI
A2: BUKU KAS UMUM
A4: Nama Madrasah | C4: : | D4: ='JUM ULA'!D4 | G4: Bulan | H4: : Jumadas Tsani
A5: Desa/Kecamatan | C5: : | D5: ='JUM ULA'!D5 -> Blu'uran, Karang Penang | G5: Halaman | H5: :
A6: Kabupaten | C6: : | D6: ='JUM ULA'!D6 -> Sampang
A8: Tanggal (Masehi) | B8: Tanggal (Hijriyah) | C8: No. Kode | D8: No. Bukti | E8: URAIAN | G8: Penerimaan | H8: Pengeluaran | I8: Saldo
G9: (Rp) | H9: (Rp) | I9: (Rp)
A10: 1 | B10: 2 | C10: 3 | D10: 4 | E10: 5 | G10: 6 | H10: 7 | I10: 8
D11: 1 | G11: =if(D11=1,'JUM ULA'!I29,"") -> 0 | I11: =IF(OR(G11<>0,H11<>0),SUM(G$11:G11)-SUM(H$11:H11),0) -> 0
E12: IMNI TSANAWIYAH | G12: 1050000 | I12: =IF(OR(G12<>0,H12<>0),SUM(G$11:G12)-SUM(H$11:H12),0) -> 1050000
E13: =IFERROR(VLOOKUP(C13,#REF!,2)," ") | I13: =IF(OR(G13<>0,H13<>0),SUM(G$11:G13)-SUM(H$11:H13),0) -> 0
E14: ID Card✅ | H14: 40000 | I14: =IF(OR(G14<>0,H14<>0),SUM(G$11:G14)-SUM(H$11:H14),0) -> 1010000
E15: Map tas kancing✅ | H15: 26000 | I15: =IF(OR(G15<>0,H15<>0),SUM(G$11:G15)-SUM(H$11:H15),0) -> 984000
E16: Kertas A4 sidu✅ | H16: 50000 | I16: =IF(OR(G16<>0,H16<>0),SUM(G$11:G16)-SUM(H$11:H16),0) -> 934000
E17: Kertas F4 sidu✅ | H17: 55000 | I17: =IF(OR(G17<>0,H17<>0),SUM(G$11:G17)-SUM(H$11:H17),0) -> 879000
E18: Transport✅ | H18: 20000 | I18: =IF(OR(G18<>0,H18<>0),SUM(G$11:G18)-SUM(H$11:H18),0) -> 859000
E19: Banner✅ | H19: 50000 | I19: =IF(OR(G19<>0,H19<>0),SUM(G$11:G19)-SUM(H$11:H19),0) -> 809000
E20: Labsoma✅ | H20: 400000 | I20: =IF(OR(G20<>0,H20<>0),SUM(G$11:G20)-SUM(H$11:H20),0) -> 409000
E21: Konsumsi✅ | H21: 100000 | I21: =IF(OR(G21<>0,H21<>0),SUM(G$11:G21)-SUM(H$11:H21),0) -> 309000
E22: Batu ampar✅ | H22: 50000 | I22: =IF(OR(G22<>0,H22<>0),SUM(G$11:G22)-SUM(H$11:H22),0) -> 259000
E23: =IFERROR(VLOOKUP(C23,#REF!,2)," ") | I23: =IF(OR(G23<>0,H23<>0),SUM(G$11:G23)-SUM(H$11:H23),0) -> 0
E24: =IFERROR(VLOOKUP(C24,#REF!,2)," ") | I24: =IF(OR(G24<>0,H24<>0),SUM(G$11:G24)-SUM(H$11:H24),0) -> 0
E25: =IFERROR(VLOOKUP(C25,#REF!,2)," ") | I25: =IF(OR(G25<>0,H25<>0),SUM(G$11:G25)-SUM(H$11:H25),0) -> 0
E26: =IFERROR(VLOOKUP(C26,#REF!,2)," ") | I26: =IF(OR(G26<>0,H26<>0),SUM(G$11:G26)-SUM(H$11:H26),0) -> 0
E27: Lain lain✅ | H27: 50000 | I27: =IF(OR(G27<>0,H27<>0),SUM(G$11:G27)-SUM(H$11:H27),0) -> 209000
E28: =IFERROR(VLOOKUP(C28,#REF!,2)," ") | I28: =IF(OR(G28<>0,H28<>0),SUM(G$11:G28)-SUM(H$11:H28),0) -> 0
G29: =SUM(G11:G28) -> 1050000 | H29: =SUM(H11:H28) -> 841000 | I29: =G29-H29 -> 209000
A30: Pada hari ................ tanggal ........... bulan.......... tahun .................. Buku Kas Umum ditutup dengan keadaan sebagai berikut :
A31: Saldo Buku Kas Umum | F31: =+I29 -> 209000
A32: Terdiri dari :
A33: Saldo Kas Tunai (isi sendiri)
A34: Saldo Bank | E34: =I29-E33 -> 209000
A35: Jumlah | F35: =SUM(E33:E34) -> 209000
A37: Mengetahui, | G37: Sampang, .............................................
A38: ='JUM ULA'!A38 -> Ketua Yayasan | G38: ='JUM ULA'!G38 -> Bendahara
A43: ='JUM ULA'!A43 -> K. KHOIRUS SHOLEH | G43: ='JUM ULA'!G43 -> ..............................................
A57: BUKU KAS UMUM
A59: Nama Sekolah | D59: :
A60: Desa/Kecamatan | D60: :
A61: Kabupaten | D61: : Sleman | H61: Halaman :
A63: Tanggal | C63: No. Kode | D63: No. Bukti | E63: URAIAN | G63: Penerimaan | H63: Pengeluaran | I63: Saldo
...

Sheet RAJAB
A2: BUKU KAS UMUM
A4: Nama Madrasah | C4: : | D4: ='JUM TSANI'!D4 | G4: Bulan | H4: : Rajab
A5: Desa/Kecamatan | C5: : | D5: ='JUM TSANI'!D5 -> Blu'uran, Karang Penang | G5: Halaman | H5: :
A6: Kabupaten | C6: : | D6: ='JUM TSANI'!D6 -> Sampang
A8: Tanggal (Masehi) | B8: Tanggal (Hijriyah) | C8: No. Kode | D8: No. Bukti | E8: URAIAN | G8: Penerimaan | H8: Pengeluaran | I8: Saldo
G9: (Rp) | H9: (Rp) | I9: (Rp)
A10: 1 | B10: 2 | C10: 3 | D10: 4 | E10: 5 | G10: 6 | H10: 7 | I10: 8
E11: Saldo Awal Bulan J. Tsani | G11: =if(D11=1,'JUM TSANI'!I29,"") | I11: =IF(OR(G11<>0,H11<>0),SUM(G$11:G11)-SUM(H$11:H11),0) -> 0
I12: =IF(OR(G12<>0,H12<>0),SUM(G$11:G12)-SUM(H$11:H12),0) -> 0
I13: =IF(OR(G13<>0,H13<>0),SUM(G$11:G13)-SUM(H$11:H13),0) -> 0
I14: =IF(OR(G14<>0,H14<>0),SUM(G$11:G14)-SUM(H$11:H14),0) -> 0
I15: =IF(OR(G15<>0,H15<>0),SUM(G$11:G15)-SUM(H$11:H15),0) -> 0
I16: =IF(OR(G16<>0,H16<>0),SUM(G$11:G16)-SUM(H$11:H16),0) -> 0
I17: =IF(OR(G17<>0,H17<>0),SUM(G$11:G17)-SUM(H$11:H17),0) -> 0
E18: =IFERROR(VLOOKUP(C18,#REF!,2)," ") | I18: =IF(OR(G18<>0,H18<>0),SUM(G$11:G18)-SUM(H$11:H18),0) -> 0
E19: =IFERROR(VLOOKUP(C19,#REF!,2)," ") | I19: =IF(OR(G19<>0,H19<>0),SUM(G$11:G19)-SUM(H$11:H19),0) -> 0
E20: =IFERROR(VLOOKUP(C20,#REF!,2)," ") | I20: =IF(OR(G20<>0,H20<>0),SUM(G$11:G20)-SUM(H$11:H20),0) -> 0
E21: =IFERROR(VLOOKUP(C21,#REF!,2)," ") | I21: =IF(OR(G21<>0,H21<>0),SUM(G$11:G21)-SUM(H$11:H21),0) -> 0
E22: =IFERROR(VLOOKUP(C22,#REF!,2)," ") | I22: =IF(OR(G22<>0,H22<>0),SUM(G$11:G22)-SUM(H$11:H22),0) -> 0
E23: =IFERROR(VLOOKUP(C23,#REF!,2)," ") | I23: =IF(OR(G23<>0,H23<>0),SUM(G$11:G23)-SUM(H$11:H23),0) -> 0
E24: =IFERROR(VLOOKUP(C24,#REF!,2)," ") | I24: =IF(OR(G24<>0,H24<>0),SUM(G$11:G24)-SUM(H$11:H24),0) -> 0
E25: =IFERROR(VLOOKUP(C25,#REF!,2)," ") | I25: =IF(OR(G25<>0,H25<>0),SUM(G$11:G25)-SUM(H$11:H25),0) -> 0
E26: =IFERROR(VLOOKUP(C26,#REF!,2)," ") | I26: =IF(OR(G26<>0,H26<>0),SUM(G$11:G26)-SUM(H$11:H26),0) -> 0
E27: =IFERROR(VLOOKUP(C27,#REF!,2)," ") | I27: =IF(OR(G27<>0,H27<>0),SUM(G$11:G27)-SUM(H$11:H27),0) -> 0
E28: =IFERROR(VLOOKUP(C28,#REF!,2)," ") | I28: =IF(OR(G28<>0,H28<>0),SUM(G$11:G28)-SUM(H$11:H28),0) -> 0
G29: =SUM(G11:G28) -> 0 | H29: =SUM(H11:H28) -> 0 | I29: =G29-H29 -> 0
A30: Pada hari ................ tanggal ........... bulan.......... tahun .................. Buku Kas Umum ditutup dengan keadaan sebagai berikut :
A31: Saldo Buku Kas Umum | F31: =+I29 -> 0
A32: Terdiri dari :
A33: Saldo Kas Tunai (isi sendiri)
A34: Saldo Bank | E34: =I29-E33 -> 0
A35: Jumlah | F35: =SUM(E33:E34) -> 0
A37: Mengetahui, | G37: Sampang, ..........................................
A38: ='JUM TSANI'!A38 -> Ketua Yayasan | G38: ='JUM TSANI'!G38 -> Bendahara
A43: ='JUM TSANI'!A43 -> K. KHOIRUS SHOLEH | G43: ='JUM TSANI'!G43 -> ..............................................
A57: BUKU KAS UMUM
A59: Nama Sekolah | D59: :
A60: Desa/Kecamatan | D60: :
A61: Kabupaten | D61: : Sleman | H61: Halaman :
A63: Tanggal | C63: No. Kode | D63: No. Bukti | E63: URAIAN | G63: Penerimaan | H63: Pengeluaran | I63: Saldo
...

Sheet SYABAN
A2: BUKU KAS UMUM
A4: Nama Madrasah | C4: : | D4: =RAJAB!D4 | G4: Bulan | H4: : Sya'ban
A5: Desa/Kecamatan | C5: : | D5: =RAJAB!D5 -> Blu'uran, Karang Penang | G5: Halaman | H5: :
A6: Kabupaten | C6: : | D6: =RAJAB!D6 -> Sampang
A8: Tanggal (Masehi) | B8: Tanggal (Hijriyah) | C8: No. Kode | D8: No. Bukti | E8: URAIAN | G8: Penerimaan | H8: Pengeluaran | I8: Saldo
G9: (Rp) | H9: (Rp) | I9: (Rp)
A10: 1 | B10: 2 | C10: 3 | D10: 4 | E10: 5 | G10: 6 | H10: 7 | I10: 8
D11: 1 | E11: Saldo Awal Bulan Rajab | G11: =if(D11=1,RAJAB!I29,"") -> 0 | I11: =IF(OR(G11<>0,H11<>0),SUM(G$11:G11)-SUM(H$11:H11),0) -> 0
E12: =IFERROR(VLOOKUP(C12,#REF!,2)," ") | I12: =IF(OR(G12<>0,H12<>0),SUM(G$11:G12)-SUM(H$11:H12),0) -> 0
E13: =IFERROR(VLOOKUP(C13,#REF!,2)," ") | I13: =IF(OR(G13<>0,H13<>0),SUM(G$11:G13)-SUM(H$11:H13),0) -> 0
E14: =IFERROR(VLOOKUP(C14,#REF!,2)," ") | I14: =IF(OR(G14<>0,H14<>0),SUM(G$11:G14)-SUM(H$11:H14),0) -> 0
E15: =IFERROR(VLOOKUP(C15,#REF!,2)," ") | I15: =IF(OR(G15<>0,H15<>0),SUM(G$11:G15)-SUM(H$11:H15),0) -> 0
E16: =IFERROR(VLOOKUP(C16,#REF!,2)," ") | I16: =IF(OR(G16<>0,H16<>0),SUM(G$11:G16)-SUM(H$11:H16),0) -> 0
E17: =IFERROR(VLOOKUP(C17,#REF!,2)," ") | I17: =IF(OR(G17<>0,H17<>0),SUM(G$11:G17)-SUM(H$11:H17),0) -> 0
E18: =IFERROR(VLOOKUP(C18,#REF!,2)," ") | I18: =IF(OR(G18<>0,H18<>0),SUM(G$11:G18)-SUM(H$11:H18),0) -> 0
E19: =IFERROR(VLOOKUP(C19,#REF!,2)," ") | I19: =IF(OR(G19<>0,H19<>0),SUM(G$11:G19)-SUM(H$11:H19),0) -> 0
E20: =IFERROR(VLOOKUP(C20,#REF!,2)," ") | I20: =IF(OR(G20<>0,H20<>0),SUM(G$11:G20)-SUM(H$11:H20),0) -> 0
E21: =IFERROR(VLOOKUP(C21,#REF!,2)," ") | I21: =IF(OR(G21<>0,H21<>0),SUM(G$11:G21)-SUM(H$11:H21),0) -> 0
E22: =IFERROR(VLOOKUP(C22,#REF!,2)," ") | I22: =IF(OR(G22<>0,H22<>0),SUM(G$11:G22)-SUM(H$11:H22),0) -> 0
E23: =IFERROR(VLOOKUP(C23,#REF!,2)," ") | I23: =IF(OR(G23<>0,H23<>0),SUM(G$11:G23)-SUM(H$11:H23),0) -> 0
... E28: =IFERROR(VLOOKUP(C28,#REF!,2)," ") | I28: =IF(OR(G28<>0,H28<>0),SUM(G$11:G28)-SUM(H$11:H28),0) -> 0
G29: =SUM(G11:G28) -> 0 | H29: =SUM(H11:H28) -> 0 | I29: =G29-H29 -> 0
A30: Pada hari ................ tanggal ........... bulan.......... tahun .................. Buku Kas Umum ditutup dengan keadaan sebagai berikut :
A31: Saldo Buku Kas Umum | F31: =+I29 -> 0
A32: Terdiri dari :
A33: Saldo Kas Tunai (isi sendiri)
A34: Saldo Bank | E34: =I29-E33 -> 0
A35: Jumlah | F35: =SUM(E33:E34) -> 0
A37: Mengetahui, | G37: Sampang, .......................................................
A38: =RAJAB!A38 -> Ketua Yayasan | G38: =RAJAB!G38 -> Bendahara
A43: =RAJAB!A43 -> K. KHOIRUS SHOLEH | G43: =RAJAB!G43 -> ..............................................
A57: BUKU KAS UMUM
A59: Nama Sekolah | D59: :
A60: Desa/Kecamatan | D60: :
A61: Kabupaten | D61: : Sleman | H61: Halaman :
A63: Tanggal | C63: No. Kode | D63: No. Bukti | E63: URAIAN | G63: Penerimaan | H63: Pengeluaran | I63: Saldo
G64: (Rp) | H64: (Rp) | I64: (Rp)
A65: 1 | C65: 2 | D65: 3 | E65: 4 | G65: 5 | H65: 6 | I65: 7
A66: 02-05-2015 | E66: Saldo bulan yang lalu | G66: =G29 -> 0 | H66: =H29 -> 0 | I66: =I29 -> 0
A67: 11-05-2015 | D67: 9 | E67: Langganan listrik bulan Mei 2015 | H67: =#REF! -> #REF! | I67: =I66-H67 -> #REF!
...

Sheet RAMADHAN
A2: BUKU KAS UMUM
A4: Nama Madrasah | C4: : | D4: =SYABAN!D4 | G4: Bulan | H4: : Ramadhan
A5: Desa/Kecamatan | C5: : | D5: =SYABAN!D5 -> Blu'uran, Karang Penang | G5: Halaman | H5: :
A6: Kabupaten | C6: : | D6: =SYABAN!D6 -> Sampang
A8: Tanggal (Masehi) | B8: Tanggal (Hijriyah) | C8: No. Kode | D8: No. Bukti | E8: URAIAN | G8: Penerimaan | H8: Pengeluaran | I8: Saldo
G9: (Rp) | H9: (Rp) | I9: (Rp)
A10: 1 | B10: 2 | C10: 3 | D10: 4 | E10: 5 | G10: 6 | H10: 7 | I10: 8
E11: Saldo Awal Bulan Sya'ban | G11: =if(D11=1,SYABAN!I29,"") | I11: =IF(OR(G11<>0,H11<>0),SUM(G$11:G11)-SUM(H$11:H11),0) -> 0
I12: =IF(OR(G12<>0,H12<>0),SUM(G$11:G12)-SUM(H$11:H12),0) -> 0
I13: =IF(OR(G13<>0,H13<>0),SUM(G$11:G13)-SUM(H$11:H13),0) -> 0
I14: =IF(OR(G14<>0,H14<>0),SUM(G$11:G14)-SUM(H$11:H14),0) -> 0
I15: =IF(OR(G15<>0,H15<>0),SUM(G$11:G15)-SUM(H$11:H15),0) -> 0
I16: =IF(OR(G16<>0,H16<>0),SUM(G$11:G16)-SUM(H$11:H16),0) -> 0
I17: =IF(OR(G17<>0,H17<>0),SUM(G$11:G17)-SUM(H$11:H17),0) -> 0
I18: =IF(OR(G18<>0,H18<>0),SUM(G$11:G18)-SUM(H$11:H18),0) -> 0
I19: =IF(OR(G19<>0,H19<>0),SUM(G$11:G19)-SUM(H$11:H19),0) -> 0
I20: =IF(OR(G20<>0,H20<>0),SUM(G$11:G20)-SUM(H$11:H20),0) -> 0
I21: =IF(OR(G21<>0,H21<>0),SUM(G$11:G21)-SUM(H$11:H21),0) -> 0
I22: =IF(OR(G22<>0,H22<>0),SUM(G$11:G22)-SUM(H$11:H22),0) -> 0
I23: =IF(OR(G23<>0,H23<>0),SUM(G$11:G23)-SUM(H$11:H23),0) -> 0
E24: =IFERROR(VLOOKUP(C24,#REF!,2)," ") | I24: =IF(OR(G24<>0,H24<>0),SUM(G$11:G24)-SUM(H$11:H24),0) -> 0
E25: =IFERROR(VLOOKUP(C25,#REF!,2)," ") | I25: =IF(OR(G25<>0,H25<>0),SUM(G$11:G25)-SUM(H$11:H25),0) -> 0
E26: =IFERROR(VLOOKUP(C26,#REF!,2)," ") | I26: =IF(OR(G26<>0,H26<>0),SUM(G$11:G26)-SUM(H$11:H26),0) -> 0
E27: =IFERROR(VLOOKUP(C27,#REF!,2)," ") | I27: =IF(OR(G27<>0,H27<>0),SUM(G$11:G27)-SUM(H$11:H27),0) -> 0
E28: =IFERROR(VLOOKUP(C28,#REF!,2)," ") | I28: =IF(OR(G28<>0,H28<>0),SUM(G$11:G28)-SUM(H$11:H28),0) -> 0
E29: =IFERROR(VLOOKUP(C29,#REF!,2)," ") | I29: =IF(OR(G29<>0,H29<>0),SUM(G$11:G29)-SUM(H$11:H29),0) -> 0
G30: =SUM(G11:G29) -> 0 | H30: =SUM(H11:H29) -> 0 | I30: =G30-H30 -> 0
A31: Pada hari ................ tanggal ........... bulan.......... tahun .................. Buku Kas Umum ditutup dengan keadaan sebagai berikut :
A32: Saldo Buku Kas Umum | F32: =+I30 -> 0
A33: Terdiri dari :
A34: Saldo Kas Tunai (isi sendiri)
A35: Saldo Bank | E35: =I30-E34 -> 0
A36: Jumlah | F36: =SUM(E34:E35) -> 0
A38: Mengetahui, | G38: Sampang, .................................................
A39: =SYABAN!A38 -> Ketua Yayasan | G39: =SYABAN!G38 -> Bendahara
A44: =SYABAN!A43 -> K. KHOIRUS SHOLEH | G44: =SYABAN!G43 -> ..............................................
A58: BUKU KAS UMUM
A60: Nama Sekolah | D60: :
A61: Desa/Kecamatan | D61: :
A62: Kabupaten | D62: : Sleman | H62: Halaman :
...
